{
    "py/object": "datatable_helper.LTS_Problem_test",
    "data": {
        "python.algorithms.CleanFileCacheTest.CleanFileCacheTest": {
            "py/object": "datatable_helper.LTS_Problem_test_entry",
            "test_name": "python.algorithms.CleanFileCacheTest.CleanFileCacheTest",
            "latest_failed_build": "445",
            "agent_name": "Mac",
            "last_failed_outcome": "Failed",
            "pipeline_name": "main_nightly_deployment_prototype",
            "past_failed_outcome": {
                "437": "Failed",
                "438": "Failed",
                "439": "Failed",
                "441": "Failed",
                "442": "Failed",
                "444": "Failed",
                "445": "Failed"
            },
            "last_stack_traces": {
                "py/object": "datatable_helper.Problem_test_trial",
                "test_name": "python.algorithms.CleanFileCacheTest.CleanFileCacheTest",
                "build": "445",
                "agent_name": "Mac",
                "trial": 3,
                "outcome": "Failed",
                "test_time": "30.56",
                "stacktrace": "FrameworkManager-[Notice] Welcome to Mantid 6.5.20221109.1600\nFrameworkManager-[Notice] Please cite: http://dx.doi.org/10.1016/j.nima.2014.07.029 and this release: http://dx.doi.org/10.5286/Software/Mantid\nCreateCacheFilename-[Notice] CreateCacheFilename started\nCreateCacheFilename-[Notice] CreateCacheFilename successful, Duration 0.00 seconds\nCreateCacheFilename-[Notice] CreateCacheFilename started\nCreateCacheFilename-[Notice] CreateCacheFilename successful, Duration 0.00 seconds\nFrameworkManager-[Notice] Welcome to Mantid 6.5.20221109.1600\nFrameworkManager-[Notice] Please cite: http://dx.doi.org/10.1016/j.nima.2014.07.029 and this release: http://dx.doi.org/10.5286/Software/Mantid\nCleanFileCache-[Notice] CleanFileCache started\nCleanFileCache-[Notice] CleanFileCache successful, Duration 0.01 seconds\n.CreateCacheFilename-[Notice] CreateCacheFilename started\nCreateCacheFilename-[Notice] CreateCacheFilename successful, Duration 0.00 seconds\nCreateCacheFilename-[Notice] CreateCacheFilename started\nCreateCacheFilename-[Notice] CreateCacheFilename successful, Duration 0.00 seconds\nFrameworkManager-[Notice] Welcome to Mantid 6.5.20221109.1600\nFrameworkManager-[Notice] Please cite: http://dx.doi.org/10.1016/j.nima.2014.07.029 and this release: http://dx.doi.org/10.5286/Software/Mantid\nCleanFileCache-[Notice] CleanFileCache started\nCleanFileCache-[Notice] CleanFileCache successful, Duration 0.00 seconds\n.CreateCacheFilename-[Notice] CreateCacheFilename started\nCreateCacheFilename-[Notice] CreateCacheFilename successful, Duration 0.00 seconds\nCreateCacheFilename-[Notice] CreateCacheFilename started\nCreateCacheFilename-[Notice] CreateCacheFilename successful, Duration 0.00 seconds\nCreateCacheFilename-[Notice] CreateCacheFilename started\nCreateCacheFilename-[Notice] CreateCacheFilename successful, Duration 0.00 seconds\nFrameworkManager-[Notice] Welcome to Mantid 6.5.20221109.1600\nFrameworkManager-[Notice] Please cite: http://dx.doi.org/10.1016/j.nima.2014.07.029 and this release: http://dx.doi.org/10.5286/Software/Mantid\nCleanFileCache-[Notice] CleanFileCache started\nCleanFileCache-[Notice] CleanFileCache successful, Duration 0.00 seconds\nF\n======================================================================\nFAIL: test3 (CleanFileCacheTest.CleanFileCache)\nCleanFileCache: &quot;age&quot; parameter\n----------------------------------------------------------------------\nTraceback (most recent call last):\n  File &quot;/Users/builder/Jenkins/workspace/main_nightly_deployment_prototype/Framework/PythonInterface/test/python/plugins/algorithms/CleanFileCacheTest.py&quot;, line 147, in test3\n    self.assertEqual(set(files_remained), set(non_cache+[cache1]))\nAssertionError: Items in the first set but not the second:\n&#x27;/tmp/tmp1th94qj9/b4fd5fc22586b9b01c0193ad550440ef7b19bf91.nxs&#x27;\n\n----------------------------------------------------------------------\nRan 3 tests in 23.990s\n\nFAILED (failures=1)\n\n          Start 2632: python.SANS.user_file.txt_parsers.toml_v1_schema_test.toml_v1_schema_test\n"
            }
        },
        "python.WorkflowAlgorithms.TransformToIqtTest.TransformToIqtTest": {
            "py/object": "datatable_helper.LTS_Problem_test_entry",
            "test_name": "python.WorkflowAlgorithms.TransformToIqtTest.TransformToIqtTest",
            "latest_failed_build": "446",
            "agent_name": "Mac",
            "last_failed_outcome": "Flake",
            "pipeline_name": "main_nightly_deployment_prototype",
            "past_failed_outcome": {
                "446": "Flake"
            },
            "last_stack_traces": {
                "py/object": "datatable_helper.Problem_test_trial",
                "test_name": "python.WorkflowAlgorithms.TransformToIqtTest.TransformToIqtTest",
                "build": "446",
                "agent_name": "Mac",
                "trial": 1,
                "outcome": "Failed",
                "test_time": "9.90",
                "stacktrace": "FrameworkManager-[Notice] Welcome to Mantid 6.5.20221109.1600\nFrameworkManager-[Notice] Please cite: http://dx.doi.org/10.1016/j.nima.2014.07.029 and this release: http://dx.doi.org/10.5286/Software/Mantid\nCreateEmptyTableWorkspace-[Notice] CreateEmptyTableWorkspace started\nCreateEmptyTableWorkspace-[Notice] CreateEmptyTableWorkspace successful, Duration 0.00 seconds\nLoad-[Notice] Load started\nLoad-[Notice] Load successful, Duration 0.53 seconds\nLoad-[Notice] Load started\nInstrumentDefinitionParser-[Warning] Attribute &#x27;mark-as&#x27; is a depricated attribute in Instrument Definition File. Please see the deprecated section of www.mantidproject.org/IDF for how to remove this warning message\nInstrumentDefinitionParser-[Warning] Attribute &#x27;mark-as&#x27; is a depricated attribute in Instrument Definition File. Please see the deprecated section of www.mantidproject.org/IDF for how to remove this warning message\nLoad-[Notice] Load successful, Duration 0.39 seconds\nTransformToIqt-[Notice] TransformToIqt started\nPython-[Notice] \nPython-[Notice] Property deltaE-mode not found\n\nCropWorkspace-[Notice] CropWorkspace started (child)\nCropWorkspace-[Notice] CropWorkspace successful, Duration 0.00 seconds\nCreateEmptyTableWorkspace-[Notice] CreateEmptyTableWorkspace started (child)\nCreateEmptyTableWorkspace-[Notice] CreateEmptyTableWorkspace successful, Duration 0.00 seconds\nDeleteWorkspace-[Notice] DeleteWorkspace started (child)\nDeleteWorkspace-[Notice] DeleteWorkspace successful, Duration 0.01 seconds\nTransformToIqt-[Notice] TransformToIqt successful, Duration 0.17 seconds\nCompareWorkspaces-[Notice] CompareWorkspaces started\nCompareWorkspaces-[Notice] The workspaces &quot;params&quot; and &quot;__TransformToIqtTest_param&quot; matched!\nCompareWorkspaces-[Notice] CompareWorkspaces successful, Duration 0.00 seconds\n.CreateEmptyTableWorkspace-[Notice] CreateEmptyTableWorkspace started\nCreateEmptyTableWorkspace-[Notice] CreateEmptyTableWorkspace successful, Duration 0.00 seconds\nLoad-[Notice] Load started\nLoad-[Notice] Load successful, Duration 0.29 seconds\nLoad-[Notice] Load started\nLoad-[Notice] Load successful, Duration 0.24 seconds\nTransformToIqt-[Notice] TransformToIqt started\nPython-[Notice] Property deltaE-mode not found\n\nPython-[Notice] Property deltaE-mode not found\n\nCropWorkspace-[Notice] CropWorkspace started (child)\nCropWorkspace-[Notice] CropWorkspace successful, Duration 0.00 seconds\nPython-[Warning] Could not get the resolution from the IPF, using 1% of the E Fixed value for the resolution: 0.01845\nCreateEmptyTableWorkspace-[Notice] CreateEmptyTableWorkspace started (child)\nCreateEmptyTableWorkspace-[Notice] CreateEmptyTableWorkspace successful, Duration 0.00 seconds\nDeleteWorkspace-[Notice] DeleteWorkspace started (child)\nDeleteWorkspace-[Notice] DeleteWorkspace successful, Duration 0.00 seconds\nTransformToIqt-[Notice] TransformToIqt successful, Duration 0.11 seconds\nCompareWorkspaces-[Notice] CompareWorkspaces started\nCompareWorkspaces-[Notice] The workspaces &quot;params&quot; and &quot;__TransformToIqtTest_param&quot; matched!\nCompareWorkspaces-[Notice] CompareWorkspaces successful, Duration 0.00 seconds\n.CreateEmptyTableWorkspace-[Notice] CreateEmptyTableWorkspace started\nCreateEmptyTableWorkspace-[Notice] CreateEmptyTableWorkspace successful, Duration 0.00 seconds\nLoad-[Notice] Load started\nLoad-[Notice] Load successful, Duration 0.23 seconds\nLoad-[Notice] Load started\nLoad-[Notice] Load successful, Duration 0.26 seconds\nTransformToIqt-[Notice] TransformToIqt started\nPython-[Notice] Property deltaE-mode not found\n\nPython-[Notice] Property deltaE-mode not found\n\nCropWorkspace-[Notice] CropWorkspace started (child)\nCropWorkspace-[Notice] CropWorkspace successful, Duration 0.00 seconds\nPython-[Warning] Could not get the resolution from the IPF, using 1% of the E Fixed value for the resolution: 0.01845\nCreateEmptyTableWorkspace-[Notice] CreateEmptyTableWorkspace started (child)\nCreateEmptyTableWorkspace-[Notice] CreateEmptyTableWorkspace successful, Duration 0.00 seconds\nDeleteWorkspace-[Notice] DeleteWorkspace started (child)\nDeleteWorkspace-[Notice] DeleteWorkspace successful, Duration 0.00 seconds\npython3.8(17175,0x7fffb7790380) malloc: *** error for object 0x7fd46933e728: incorrect checksum for freed object - object was probably modified after being freed.\n*** set a breakpoint in malloc_error_break to debug\nSubprocess aborted\n\n          Start 1694: python.WorkflowAlgorithms.TransformToIqtTest.TransformToIqtTest\n"
            }
        },
        "python.MuonQt5.fit_function_options_view_test.fit_function_options_view_test": {
            "py/object": "datatable_helper.LTS_Problem_test_entry",
            "test_name": "python.MuonQt5.fit_function_options_view_test.fit_function_options_view_test",
            "latest_failed_build": "451",
            "agent_name": "Mac",
            "last_failed_outcome": "Flake",
            "pipeline_name": "main_nightly_deployment_prototype",
            "past_failed_outcome": {
                "451": "Flake"
            },
            "last_stack_traces": {
                "py/object": "datatable_helper.Problem_test_trial",
                "test_name": "python.MuonQt5.fit_function_options_view_test.fit_function_options_view_test",
                "build": "451",
                "agent_name": "Mac",
                "trial": 1,
                "outcome": "Failed",
                "test_time": "10.86",
                "stacktrace": "FrameworkManager-[Notice] Welcome to Mantid 6.5.20221116.1431\nFrameworkManager-[Notice] Please cite: http://dx.doi.org/10.1016/j.nima.2014.07.029 and this release: http://dx.doi.org/10.5286/Software/Mantid\nEEEEEEEEEEEEEEEEEEE\n======================================================================\nERROR: test_that_clear_fit_status_will_clear_the_fit_status_and_chi_squared (fit_function_options_view_test.FitFunctionOptionsViewTest)\n----------------------------------------------------------------------\nAttributeError: &#x27;FitFunctionOptionsView&#x27; object has no attribute &#x27;y&#x27;\n\nThe above exception was the direct cause of the following exception:\n\nTraceback (most recent call last):\n  File &quot;/Users/builder/Jenkins/workspace/main_nightly_deployment_prototype/qt/python/mantidqtinterfaces/test/Muon/fitting_widgets/basic_fitting/fit_function_options_view_test.py&quot;, line 26, in setUp\n    self.view = FitFunctionOptionsView()\n  File &quot;/Users/builder/Jenkins/workspace/main_nightly_deployment_prototype/qt/python/mantidqtinterfaces/mantidqtinterfaces/Muon/GUI/Common/fitting_widgets/basic_fitting/fit_function_options_view.py&quot;, line 48, in __init__\n    self.setupUi(self)\n  File &quot;&lt;string&gt;&quot;, line 71, in setupUi\nSystemError: &lt;built-in function connectSlotsByName&gt; returned a result with an error set\n\n======================================================================\nERROR: test_that_it_is_possible_to_set_the_end_x_to_a_different_value (fit_function_options_view_test.FitFunctionOptionsViewTest)\n----------------------------------------------------------------------\nAttributeError: &#x27;FitFunctionOptionsView&#x27; object has no attribute &#x27;y&#x27;\n\nThe above exception was the direct cause of the following exception:\n\nTraceback (most recent call last):\n  File &quot;/Users/builder/Jenkins/workspace/main_nightly_deployment_prototype/qt/python/mantidqtinterfaces/test/Muon/fitting_widgets/basic_fitting/fit_function_options_view_test.py&quot;, line 26, in setUp\n    self.view = FitFunctionOptionsView()\n  File &quot;/Users/builder/Jenkins/workspace/main_nightly_deployment_prototype/qt/python/mantidqtinterfaces/mantidqtinterfaces/Muon/GUI/Common/fitting_widgets/basic_fitting/fit_function_options_view.py&quot;, line 48, in __init__\n    self.setupUi(self)\n  File &quot;&lt;string&gt;&quot;, line 71, in setupUi\nSystemError: &lt;built-in function connectSlotsByName&gt; returned a result with an error set\n\n======================================================================\nERROR: test_that_it_is_possible_to_set_the_start_x_to_a_different_value (fit_function_options_view_test.FitFunctionOptionsViewTest)\n----------------------------------------------------------------------\nAttributeError: &#x27;FitFunctionOptionsView&#x27; object has no attribute &#x27;y&#x27;\n\nThe above exception was the direct cause of the following exception:\n\nTraceback (most recent call last):\n  File &quot;/Users/builder/Jenkins/workspace/main_nightly_deployment_prototype/qt/python/mantidqtinterfaces/test/Muon/fitting_widgets/basic_fitting/fit_function_options_view_test.py&quot;, line 26, in setUp\n    self.view = FitFunctionOptionsView()\n  File &quot;/Users/builder/Jenkins/workspace/main_nightly_deployment_prototype/qt/python/mantidqtinterfaces/mantidqtinterfaces/Muon/GUI/Common/fitting_widgets/basic_fitting/fit_function_options_view.py&quot;, line 48, in __init__\n    self.setupUi(self)\n  File &quot;&lt;string&gt;&quot;, line 71, in setupUi\nSystemError: &lt;built-in function connectSlotsByName&gt; returned a result with an error set\n\n======================================================================\nERROR: test_that_set_covariance_button_enabled_can_disable_the_covariance_button (fit_function_options_view_test.FitFunctionOptionsViewTest)\n----------------------------------------------------------------------\nAttributeError: &#x27;FitFunctionOptionsView&#x27; object has no attribute &#x27;y&#x27;\n\nThe above exception was the direct cause of the following exception:\n\nTraceback (most recent call last):\n  File &quot;/Users/builder/Jenkins/workspace/main_nightly_deployment_prototype/qt/python/mantidqtinterfaces/test/Muon/fitting_widgets/basic_fitting/fit_function_options_view_test.py&quot;, line 26, in setUp\n    self.view = FitFunctionOptionsView()\n  File &quot;/Users/builder/Jenkins/workspace/main_nightly_deployment_prototype/qt/python/mantidqtinterfaces/mantidqtinterfaces/Muon/GUI/Common/fitting_widgets/basic_fitting/fit_function_options_view.py&quot;, line 48, in __init__\n    self.setupUi(self)\n  File &quot;&lt;string&gt;&quot;, line 71, in setupUi\nSystemError: &lt;built-in function connectSlotsByName&gt; returned a result with an error set\n\n======================================================================\nERROR: test_that_set_covariance_button_enabled_can_enable_the_covariance_button (fit_function_options_view_test.FitFunctionOptionsViewTest)\n----------------------------------------------------------------------\nAttributeError: &#x27;FitFunctionOptionsView&#x27; object has no attribute &#x27;y&#x27;\n\nThe above exception was the direct cause of the following exception:\n\nTraceback (most recent call last):\n  File &quot;/Users/builder/Jenkins/workspace/main_nightly_deployment_prototype/qt/python/mantidqtinterfaces/test/Muon/fitting_widgets/basic_fitting/fit_function_options_view_test.py&quot;, line 26, in setUp\n    self.view = FitFunctionOptionsView()\n  File &quot;/Users/builder/Jenkins/workspace/main_nightly_deployment_prototype/qt/python/mantidqtinterfaces/mantidqtinterfaces/Muon/GUI/Common/fitting_widgets/basic_fitting/fit_function_options_view.py&quot;, line 48, in __init__\n    self.setupUi(self)\n  File &quot;&lt;string&gt;&quot;, line 71, in setupUi\nSystemError: &lt;built-in function connectSlotsByName&gt; returned a result with an error set\n\n======================================================================\nERROR: test_that_set_current_dataset_index_will_set_the_current_dataset_index_in_the_function_browser (fit_function_options_view_test.FitFunctionOptionsViewTest)\n----------------------------------------------------------------------\nAttributeError: &#x27;FitFunctionOptionsView&#x27; object has no attribute &#x27;y&#x27;\n\nThe above exception was the direct cause of the following exception:\n\nTraceback (most recent call last):\n  File &quot;/Users/builder/Jenkins/workspace/main_nightly_deployment_prototype/qt/python/mantidqtinterfaces/test/Muon/fitting_widgets/basic_fitting/fit_function_options_view_test.py&quot;, line 26, in setUp\n    self.view = FitFunctionOptionsView()\n  File &quot;/Users/builder/Jenkins/workspace/main_nightly_deployment_prototype/qt/python/mantidqtinterfaces/mantidqtinterfaces/Muon/GUI/Common/fitting_widgets/basic_fitting/fit_function_options_view.py&quot;, line 48, in __init__\n    self.setupUi(self)\n  File &quot;&lt;string&gt;&quot;, line 71, in setupUi\nSystemError: &lt;built-in function connectSlotsByName&gt; returned a result with an error set\n\n======================================================================\nERROR: test_that_set_datasets_in_function_browser_will_set_the_datasets_in_the_function_browser (fit_function_options_view_test.FitFunctionOptionsViewTest)\n----------------------------------------------------------------------\nAttributeError: &#x27;FitFunctionOptionsView&#x27; object has no attribute &#x27;y&#x27;\n\nThe above exception was the direct cause of the following exception:\n\nTraceback (most recent call last):\n  File &quot;/Users/builder/Jenkins/workspace/main_nightly_deployment_prototype/qt/python/mantidqtinterfaces/test/Muon/fitting_widgets/basic_fitting/fit_function_options_view_test.py&quot;, line 26, in setUp\n    self.view = FitFunctionOptionsView()\n  File &quot;/Users/builder/Jenkins/workspace/main_nightly_deployment_prototype/qt/python/mantidqtinterfaces/mantidqtinterfaces/Muon/GUI/Common/fitting_widgets/basic_fitting/fit_function_options_view.py&quot;, line 48, in __init__\n    self.setupUi(self)\n  File &quot;&lt;string&gt;&quot;, line 71, in setupUi\nSystemError: &lt;built-in function connectSlotsByName&gt; returned a result with an error set\n\n======================================================================\nERROR: test_that_set_fit_function_will_set_the_function_in_the_browser (fit_function_options_view_test.FitFunctionOptionsViewTest)\n----------------------------------------------------------------------\nAttributeError: &#x27;FitFunctionOptionsView&#x27; object has no attribute &#x27;y&#x27;\n\nThe above exception was the direct cause of the following exception:\n\nTraceback (most recent call last):\n  File &quot;/Users/builder/Jenkins/workspace/main_nightly_deployment_prototype/qt/python/mantidqtinterfaces/test/Muon/fitting_widgets/basic_fitting/fit_function_options_view_test.py&quot;, line 26, in setUp\n    self.view = FitFunctionOptionsView()\n  File &quot;/Users/builder/Jenkins/workspace/main_nightly_deployment_prototype/qt/python/mantidqtinterfaces/mantidqtinterfaces/Muon/GUI/Common/fitting_widgets/basic_fitting/fit_function_options_view.py&quot;, line 48, in __init__\n    self.setupUi(self)\n  File &quot;&lt;string&gt;&quot;, line 71, in setupUi\nSystemError: &lt;built-in function connectSlotsByName&gt; returned a result with an error set\n\n======================================================================\nERROR: test_that_show_normalised_covariance_matrix_will_not_raise_an_error (fit_function_options_view_test.FitFunctionOptionsViewTest)\n----------------------------------------------------------------------\nAttributeError: &#x27;FitFunctionOptionsView&#x27; object has no attribute &#x27;y&#x27;\n\nThe above exception was the direct cause of the following exception:\n\nTraceback (most recent call last):\n  File &quot;/Users/builder/Jenkins/workspace/main_nightly_deployment_prototype/qt/python/mantidqtinterfaces/test/Muon/fitting_widgets/basic_fitting/fit_function_options_view_test.py&quot;, line 26, in setUp\n    self.view = FitFunctionOptionsView()\n  File &quot;/Users/builder/Jenkins/workspace/main_nightly_deployment_prototype/qt/python/mantidqtinterfaces/mantidqtinterfaces/Muon/GUI/Common/fitting_widgets/basic_fitting/fit_function_options_view.py&quot;, line 48, in __init__\n    self.setupUi(self)\n  File &quot;&lt;string&gt;&quot;, line 71, in setupUi\nSystemError: &lt;built-in function connectSlotsByName&gt; returned a result with an error set\n\n======================================================================\nERROR: test_that_the_fit_to_raw_checkbox_value_can_be_changed_as_expected (fit_function_options_view_test.FitFunctionOptionsViewTest)\n----------------------------------------------------------------------\nAttributeError: &#x27;FitFunctionOptionsView&#x27; object has no attribute &#x27;y&#x27;\n\nThe above exception was the direct cause of the following exception:\n\nTraceback (most recent call last):\n  File &quot;/Users/builder/Jenkins/workspace/main_nightly_deployment_prototype/qt/python/mantidqtinterfaces/test/Muon/fitting_widgets/basic_fitting/fit_function_options_view_test.py&quot;, line 26, in setUp\n    self.view = FitFunctionOptionsView()\n  File &quot;/Users/builder/Jenkins/workspace/main_nightly_deployment_prototype/qt/python/mantidqtinterfaces/mantidqtinterfaces/Muon/GUI/Common/fitting_widgets/basic_fitting/fit_function_options_view.py&quot;, line 48, in __init__\n    self.setupUi(self)\n  File &quot;&lt;string&gt;&quot;, line 71, in setupUi\nSystemError: &lt;built-in function connectSlotsByName&gt; returned a result with an error set\n\n======================================================================\nERROR: test_that_the_function_name_can_be_changed_as_expected (fit_function_options_view_test.FitFunctionOptionsViewTest)\n----------------------------------------------------------------------\nAttributeError: &#x27;FitFunctionOptionsView&#x27; object has no attribute &#x27;y&#x27;\n\nThe above exception was the direct cause of the following exception:\n\nTraceback (most recent call last):\n  File &quot;/Users/builder/Jenkins/workspace/main_nightly_deployment_prototype/qt/python/mantidqtinterfaces/test/Muon/fitting_widgets/basic_fitting/fit_function_options_view_test.py&quot;, line 26, in setUp\n    self.view = FitFunctionOptionsView()\n  File &quot;/Users/builder/Jenkins/workspace/main_nightly_deployment_prototype/qt/python/mantidqtinterfaces/mantidqtinterfaces/Muon/GUI/Common/fitting_widgets/basic_fitting/fit_function_options_view.py&quot;, line 48, in __init__\n    self.setupUi(self)\n  File &quot;&lt;string&gt;&quot;, line 71, in setupUi\nSystemError: &lt;built-in function connectSlotsByName&gt; returned a result with an error set\n\n======================================================================\nERROR: test_that_the_view_has_been_initialized_with_the_raw_data_option_hidden (fit_function_options_view_test.FitFunctionOptionsViewTest)\n----------------------------------------------------------------------\nAttributeError: &#x27;FitFunctionOptionsView&#x27; object has no attribute &#x27;y&#x27;\n\nThe above exception was the direct cause of the following exception:\n\nTraceback (most recent call last):\n  File &quot;/Users/builder/Jenkins/workspace/main_nightly_deployment_prototype/qt/python/mantidqtinterfaces/test/Muon/fitting_widgets/basic_fitting/fit_function_options_view_test.py&quot;, line 26, in setUp\n    self.view = FitFunctionOptionsView()\n  File &quot;/Users/builder/Jenkins/workspace/main_nightly_deployment_prototype/qt/python/mantidqtinterfaces/mantidqtinterfaces/Muon/GUI/Common/fitting_widgets/basic_fitting/fit_function_options_view.py&quot;, line 48, in __init__\n    self.setupUi(self)\n  File &quot;&lt;string&gt;&quot;, line 71, in setupUi\nSystemError: &lt;built-in function connectSlotsByName&gt; returned a result with an error set\n\n======================================================================\nERROR: test_that_the_view_has_been_initialized_with_the_raw_data_option_shown (fit_function_options_view_test.FitFunctionOptionsViewTest)\n----------------------------------------------------------------------\nAttributeError: &#x27;FitFunctionOptionsView&#x27; object has no attribute &#x27;y&#x27;\n\nThe above exception was the direct cause of the following exception:\n\nTraceback (most recent call last):\n  File &quot;/Users/builder/Jenkins/workspace/main_nightly_deployment_prototype/qt/python/mantidqtinterfaces/test/Muon/fitting_widgets/basic_fitting/fit_function_options_view_test.py&quot;, line 26, in setUp\n    self.view = FitFunctionOptionsView()\n  File &quot;/Users/builder/Jenkins/workspace/main_nightly_deployment_prototype/qt/python/mantidqtinterfaces/mantidqtinterfaces/Muon/GUI/Common/fitting_widgets/basic_fitting/fit_function_options_view.py&quot;, line 48, in __init__\n    self.setupUi(self)\n  File &quot;&lt;string&gt;&quot;, line 71, in setupUi\nSystemError: &lt;built-in function connectSlotsByName&gt; returned a result with an error set\n\n======================================================================\nERROR: test_that_update_fit_status_labels_will_display_fit_successful_if_all_fits_are_successful (fit_function_options_view_test.FitFunctionOptionsViewTest)\n----------------------------------------------------------------------\nAttributeError: &#x27;FitFunctionOptionsView&#x27; object has no attribute &#x27;y&#x27;\n\nThe above exception was the direct cause of the following exception:\n\nTraceback (most recent call last):\n  File &quot;/Users/builder/Jenkins/workspace/main_nightly_deployment_prototype/qt/python/mantidqtinterfaces/test/Muon/fitting_widgets/basic_fitting/fit_function_options_view_test.py&quot;, line 26, in setUp\n    self.view = FitFunctionOptionsView()\n  File &quot;/Users/builder/Jenkins/workspace/main_nightly_deployment_prototype/qt/python/mantidqtinterfaces/mantidqtinterfaces/Muon/GUI/Common/fitting_widgets/basic_fitting/fit_function_options_view.py&quot;, line 48, in __init__\n    self.setupUi(self)\n  File &quot;&lt;string&gt;&quot;, line 71, in setupUi\nSystemError: &lt;built-in function connectSlotsByName&gt; returned a result with an error set\n\n======================================================================\nERROR: test_that_update_fit_status_labels_will_display_fits_failed_if_some_of_the_fits_fail (fit_function_options_view_test.FitFunctionOptionsViewTest)\n----------------------------------------------------------------------\nAttributeError: &#x27;FitFunctionOptionsView&#x27; object has no attribute &#x27;y&#x27;\n\nThe above exception was the direct cause of the following exception:\n\nTraceback (most recent call last):\n  File &quot;/Users/builder/Jenkins/workspace/main_nightly_deployment_prototype/qt/python/mantidqtinterfaces/test/Muon/fitting_widgets/basic_fitting/fit_function_options_view_test.py&quot;, line 26, in setUp\n    self.view = FitFunctionOptionsView()\n  File &quot;/Users/builder/Jenkins/workspace/main_nightly_deployment_prototype/qt/python/mantidqtinterfaces/mantidqtinterfaces/Muon/GUI/Common/fitting_widgets/basic_fitting/fit_function_options_view.py&quot;, line 48, in __init__\n    self.setupUi(self)\n  File &quot;&lt;string&gt;&quot;, line 71, in setupUi\nSystemError: &lt;built-in function connectSlotsByName&gt; returned a result with an error set\n\n======================================================================\nERROR: test_that_update_fit_status_labels_will_display_no_fit_if_the_success_list_is_empty (fit_function_options_view_test.FitFunctionOptionsViewTest)\n----------------------------------------------------------------------\nAttributeError: &#x27;FitFunctionOptionsView&#x27; object has no attribute &#x27;y&#x27;\n\nThe above exception was the direct cause of the following exception:\n\nTraceback (most recent call last):\n  File &quot;/Users/builder/Jenkins/workspace/main_nightly_deployment_prototype/qt/python/mantidqtinterfaces/test/Muon/fitting_widgets/basic_fitting/fit_function_options_view_test.py&quot;, line 26, in setUp\n    self.view = FitFunctionOptionsView()\n  File &quot;/Users/builder/Jenkins/workspace/main_nightly_deployment_prototype/qt/python/mantidqtinterfaces/mantidqtinterfaces/Muon/GUI/Common/fitting_widgets/basic_fitting/fit_function_options_view.py&quot;, line 48, in __init__\n    self.setupUi(self)\n  File &quot;&lt;string&gt;&quot;, line 71, in setupUi\nSystemError: &lt;built-in function connectSlotsByName&gt; returned a result with an error set\n\n======================================================================\nERROR: test_that_update_function_browser_parameters_will_clear_the_function_if_the_function_provided_is_none (fit_function_options_view_test.FitFunctionOptionsViewTest)\n----------------------------------------------------------------------\nAttributeError: &#x27;FitFunctionOptionsView&#x27; object has no attribute &#x27;y&#x27;\n\nThe above exception was the direct cause of the following exception:\n\nTraceback (most recent call last):\n  File &quot;/Users/builder/Jenkins/workspace/main_nightly_deployment_prototype/qt/python/mantidqtinterfaces/test/Muon/fitting_widgets/basic_fitting/fit_function_options_view_test.py&quot;, line 26, in setUp\n    self.view = FitFunctionOptionsView()\n  File &quot;/Users/builder/Jenkins/workspace/main_nightly_deployment_prototype/qt/python/mantidqtinterfaces/mantidqtinterfaces/Muon/GUI/Common/fitting_widgets/basic_fitting/fit_function_options_view.py&quot;, line 48, in __init__\n    self.setupUi(self)\n  File &quot;&lt;string&gt;&quot;, line 71, in setupUi\nSystemError: &lt;built-in function connectSlotsByName&gt; returned a result with an error set\n\n======================================================================\nERROR: test_that_update_function_browser_parameters_will_set_the_function_if_in_simultaneous_mode (fit_function_options_view_test.FitFunctionOptionsViewTest)\n----------------------------------------------------------------------\nAttributeError: &#x27;FitFunctionOptionsView&#x27; object has no attribute &#x27;y&#x27;\n\nThe above exception was the direct cause of the following exception:\n\nTraceback (most recent call last):\n  File &quot;/Users/builder/Jenkins/workspace/main_nightly_deployment_prototype/qt/python/mantidqtinterfaces/test/Muon/fitting_widgets/basic_fitting/fit_function_options_view_test.py&quot;, line 26, in setUp\n    self.view = FitFunctionOptionsView()\n  File &quot;/Users/builder/Jenkins/workspace/main_nightly_deployment_prototype/qt/python/mantidqtinterfaces/mantidqtinterfaces/Muon/GUI/Common/fitting_widgets/basic_fitting/fit_function_options_view.py&quot;, line 48, in __init__\n    self.setupUi(self)\n  File &quot;&lt;string&gt;&quot;, line 71, in setupUi\nSystemError: &lt;built-in function connectSlotsByName&gt; returned a result with an error set\n\n======================================================================\nERROR: test_that_update_function_browser_parameters_will_update_the_parameters_of_the_function_for_single_fit (fit_function_options_view_test.FitFunctionOptionsViewTest)\n----------------------------------------------------------------------\nAttributeError: &#x27;FitFunctionOptionsView&#x27; object has no attribute &#x27;y&#x27;\n\nThe above exception was the direct cause of the following exception:\n\nTraceback (most recent call last):\n  File &quot;/Users/builder/Jenkins/workspace/main_nightly_deployment_prototype/qt/python/mantidqtinterfaces/test/Muon/fitting_widgets/basic_fitting/fit_function_options_view_test.py&quot;, line 26, in setUp\n    self.view = FitFunctionOptionsView()\n  File &quot;/Users/builder/Jenkins/workspace/main_nightly_deployment_prototype/qt/python/mantidqtinterfaces/mantidqtinterfaces/Muon/GUI/Common/fitting_widgets/basic_fitting/fit_function_options_view.py&quot;, line 48, in __init__\n    self.setupUi(self)\n  File &quot;&lt;string&gt;&quot;, line 71, in setupUi\nSystemError: &lt;built-in function connectSlotsByName&gt; returned a result with an error set\n\n----------------------------------------------------------------------\nRan 19 tests in 1.152s\n\nFAILED (errors=19)\n\n          Start 2179: python.MuonQt5.fit_function_options_view_test.fit_function_options_view_test\n"
            }
        }
    }
}