{
    "data": [
        {
            "test_name": "python.MuonQt5.fit_function_options_view_test.fit_function_options_view_test",
            "latest_failed_build": "451",
            "agent_name": "Mac",
            "last_failed_outcome": "Flake",
            "pipeline_name": "main_nightly_deployment_prototype",
            "problem_count": 1,
            "past_outcome": {
                "build_keys": [
                    "458",
                    "457",
                    "456",
                    "455",
                    "454",
                    "453",
                    "452",
                    "451",
                    "450",
                    "449"
                ],
                "past_outcome_list": [
                    "None",
                    "Passed",
                    "Passed",
                    "Passed",
                    "Passed",
                    "Passed",
                    "Passed",
                    "Flake",
                    "Passed",
                    "Passed"
                ]
            },
            "last_stack_traces": {
                "test_name": "python.MuonQt5.fit_function_options_view_test.fit_function_options_view_test",
                "build": "451",
                "agent_name": "Mac",
                "trial": 1,
                "outcome": "Failed",
                "test_time": "10.86",
                "stacktrace": "FrameworkManager-[Notice] Welcome to Mantid 6.5.20221116.1431\nFrameworkManager-[Notice] Please cite: http://dx.doi.org/10.1016/j.nima.2014.07.029 and this release: http://dx.doi.org/10.5286/Software/Mantid\nEEEEEEEEEEEEEEEEEEE\n======================================================================\nERROR: test_that_clear_fit_status_will_clear_the_fit_status_and_chi_squared (fit_function_options_view_test.FitFunctionOptionsViewTest)\n----------------------------------------------------------------------\nAttributeError: &#x27;FitFunctionOptionsView&#x27; object has no attribute &#x27;y&#x27;\n\nThe above exception was the direct cause of the following exception:\n\nTraceback (most recent call last):\n  File &quot;/Users/builder/Jenkins/workspace/main_nightly_deployment_prototype/qt/python/mantidqtinterfaces/test/Muon/fitting_widgets/basic_fitting/fit_function_options_view_test.py&quot;, line 26, in setUp\n    self.view = FitFunctionOptionsView()\n  File &quot;/Users/builder/Jenkins/workspace/main_nightly_deployment_prototype/qt/python/mantidqtinterfaces/mantidqtinterfaces/Muon/GUI/Common/fitting_widgets/basic_fitting/fit_function_options_view.py&quot;, line 48, in __init__\n    self.setupUi(self)\n  File &quot;&lt;string&gt;&quot;, line 71, in setupUi\nSystemError: &lt;built-in function connectSlotsByName&gt; returned a result with an error set\n\n======================================================================\nERROR: test_that_it_is_possible_to_set_the_end_x_to_a_different_value (fit_function_options_view_test.FitFunctionOptionsViewTest)\n----------------------------------------------------------------------\nAttributeError: &#x27;FitFunctionOptionsView&#x27; object has no attribute &#x27;y&#x27;\n\nThe above exception was the direct cause of the following exception:\n\nTraceback (most recent call last):\n  File &quot;/Users/builder/Jenkins/workspace/main_nightly_deployment_prototype/qt/python/mantidqtinterfaces/test/Muon/fitting_widgets/basic_fitting/fit_function_options_view_test.py&quot;, line 26, in setUp\n    self.view = FitFunctionOptionsView()\n  File &quot;/Users/builder/Jenkins/workspace/main_nightly_deployment_prototype/qt/python/mantidqtinterfaces/mantidqtinterfaces/Muon/GUI/Common/fitting_widgets/basic_fitting/fit_function_options_view.py&quot;, line 48, in __init__\n    self.setupUi(self)\n  File &quot;&lt;string&gt;&quot;, line 71, in setupUi\nSystemError: &lt;built-in function connectSlotsByName&gt; returned a result with an error set\n\n======================================================================\nERROR: test_that_it_is_possible_to_set_the_start_x_to_a_different_value (fit_function_options_view_test.FitFunctionOptionsViewTest)\n----------------------------------------------------------------------\nAttributeError: &#x27;FitFunctionOptionsView&#x27; object has no attribute &#x27;y&#x27;\n\nThe above exception was the direct cause of the following exception:\n\nTraceback (most recent call last):\n  File &quot;/Users/builder/Jenkins/workspace/main_nightly_deployment_prototype/qt/python/mantidqtinterfaces/test/Muon/fitting_widgets/basic_fitting/fit_function_options_view_test.py&quot;, line 26, in setUp\n    self.view = FitFunctionOptionsView()\n  File &quot;/Users/builder/Jenkins/workspace/main_nightly_deployment_prototype/qt/python/mantidqtinterfaces/mantidqtinterfaces/Muon/GUI/Common/fitting_widgets/basic_fitting/fit_function_options_view.py&quot;, line 48, in __init__\n    self.setupUi(self)\n  File &quot;&lt;string&gt;&quot;, line 71, in setupUi\nSystemError: &lt;built-in function connectSlotsByName&gt; returned a result with an error set\n\n======================================================================\nERROR: test_that_set_covariance_button_enabled_can_disable_the_covariance_button (fit_function_options_view_test.FitFunctionOptionsViewTest)\n----------------------------------------------------------------------\nAttributeError: &#x27;FitFunctionOptionsView&#x27; object has no attribute &#x27;y&#x27;\n\nThe above exception was the direct cause of the following exception:\n\nTraceback (most recent call last):\n  File &quot;/Users/builder/Jenkins/workspace/main_nightly_deployment_prototype/qt/python/mantidqtinterfaces/test/Muon/fitting_widgets/basic_fitting/fit_function_options_view_test.py&quot;, line 26, in setUp\n    self.view = FitFunctionOptionsView()\n  File &quot;/Users/builder/Jenkins/workspace/main_nightly_deployment_prototype/qt/python/mantidqtinterfaces/mantidqtinterfaces/Muon/GUI/Common/fitting_widgets/basic_fitting/fit_function_options_view.py&quot;, line 48, in __init__\n    self.setupUi(self)\n  File &quot;&lt;string&gt;&quot;, line 71, in setupUi\nSystemError: &lt;built-in function connectSlotsByName&gt; returned a result with an error set\n\n======================================================================\nERROR: test_that_set_covariance_button_enabled_can_enable_the_covariance_button (fit_function_options_view_test.FitFunctionOptionsViewTest)\n----------------------------------------------------------------------\nAttributeError: &#x27;FitFunctionOptionsView&#x27; object has no attribute &#x27;y&#x27;\n\nThe above exception was the direct cause of the following exception:\n\nTraceback (most recent call last):\n  File &quot;/Users/builder/Jenkins/workspace/main_nightly_deployment_prototype/qt/python/mantidqtinterfaces/test/Muon/fitting_widgets/basic_fitting/fit_function_options_view_test.py&quot;, line 26, in setUp\n    self.view = FitFunctionOptionsView()\n  File &quot;/Users/builder/Jenkins/workspace/main_nightly_deployment_prototype/qt/python/mantidqtinterfaces/mantidqtinterfaces/Muon/GUI/Common/fitting_widgets/basic_fitting/fit_function_options_view.py&quot;, line 48, in __init__\n    self.setupUi(self)\n  File &quot;&lt;string&gt;&quot;, line 71, in setupUi\nSystemError: &lt;built-in function connectSlotsByName&gt; returned a result with an error set\n\n======================================================================\nERROR: test_that_set_current_dataset_index_will_set_the_current_dataset_index_in_the_function_browser (fit_function_options_view_test.FitFunctionOptionsViewTest)\n----------------------------------------------------------------------\nAttributeError: &#x27;FitFunctionOptionsView&#x27; object has no attribute &#x27;y&#x27;\n\nThe above exception was the direct cause of the following exception:\n\nTraceback (most recent call last):\n  File &quot;/Users/builder/Jenkins/workspace/main_nightly_deployment_prototype/qt/python/mantidqtinterfaces/test/Muon/fitting_widgets/basic_fitting/fit_function_options_view_test.py&quot;, line 26, in setUp\n    self.view = FitFunctionOptionsView()\n  File &quot;/Users/builder/Jenkins/workspace/main_nightly_deployment_prototype/qt/python/mantidqtinterfaces/mantidqtinterfaces/Muon/GUI/Common/fitting_widgets/basic_fitting/fit_function_options_view.py&quot;, line 48, in __init__\n    self.setupUi(self)\n  File &quot;&lt;string&gt;&quot;, line 71, in setupUi\nSystemError: &lt;built-in function connectSlotsByName&gt; returned a result with an error set\n\n======================================================================\nERROR: test_that_set_datasets_in_function_browser_will_set_the_datasets_in_the_function_browser (fit_function_options_view_test.FitFunctionOptionsViewTest)\n----------------------------------------------------------------------\nAttributeError: &#x27;FitFunctionOptionsView&#x27; object has no attribute &#x27;y&#x27;\n\nThe above exception was the direct cause of the following exception:\n\nTraceback (most recent call last):\n  File &quot;/Users/builder/Jenkins/workspace/main_nightly_deployment_prototype/qt/python/mantidqtinterfaces/test/Muon/fitting_widgets/basic_fitting/fit_function_options_view_test.py&quot;, line 26, in setUp\n    self.view = FitFunctionOptionsView()\n  File &quot;/Users/builder/Jenkins/workspace/main_nightly_deployment_prototype/qt/python/mantidqtinterfaces/mantidqtinterfaces/Muon/GUI/Common/fitting_widgets/basic_fitting/fit_function_options_view.py&quot;, line 48, in __init__\n    self.setupUi(self)\n  File &quot;&lt;string&gt;&quot;, line 71, in setupUi\nSystemError: &lt;built-in function connectSlotsByName&gt; returned a result with an error set\n\n======================================================================\nERROR: test_that_set_fit_function_will_set_the_function_in_the_browser (fit_function_options_view_test.FitFunctionOptionsViewTest)\n----------------------------------------------------------------------\nAttributeError: &#x27;FitFunctionOptionsView&#x27; object has no attribute &#x27;y&#x27;\n\nThe above exception was the direct cause of the following exception:\n\nTraceback (most recent call last):\n  File &quot;/Users/builder/Jenkins/workspace/main_nightly_deployment_prototype/qt/python/mantidqtinterfaces/test/Muon/fitting_widgets/basic_fitting/fit_function_options_view_test.py&quot;, line 26, in setUp\n    self.view = FitFunctionOptionsView()\n  File &quot;/Users/builder/Jenkins/workspace/main_nightly_deployment_prototype/qt/python/mantidqtinterfaces/mantidqtinterfaces/Muon/GUI/Common/fitting_widgets/basic_fitting/fit_function_options_view.py&quot;, line 48, in __init__\n    self.setupUi(self)\n  File &quot;&lt;string&gt;&quot;, line 71, in setupUi\nSystemError: &lt;built-in function connectSlotsByName&gt; returned a result with an error set\n\n======================================================================\nERROR: test_that_show_normalised_covariance_matrix_will_not_raise_an_error (fit_function_options_view_test.FitFunctionOptionsViewTest)\n----------------------------------------------------------------------\nAttributeError: &#x27;FitFunctionOptionsView&#x27; object has no attribute &#x27;y&#x27;\n\nThe above exception was the direct cause of the following exception:\n\nTraceback (most recent call last):\n  File &quot;/Users/builder/Jenkins/workspace/main_nightly_deployment_prototype/qt/python/mantidqtinterfaces/test/Muon/fitting_widgets/basic_fitting/fit_function_options_view_test.py&quot;, line 26, in setUp\n    self.view = FitFunctionOptionsView()\n  File &quot;/Users/builder/Jenkins/workspace/main_nightly_deployment_prototype/qt/python/mantidqtinterfaces/mantidqtinterfaces/Muon/GUI/Common/fitting_widgets/basic_fitting/fit_function_options_view.py&quot;, line 48, in __init__\n    self.setupUi(self)\n  File &quot;&lt;string&gt;&quot;, line 71, in setupUi\nSystemError: &lt;built-in function connectSlotsByName&gt; returned a result with an error set\n\n======================================================================\nERROR: test_that_the_fit_to_raw_checkbox_value_can_be_changed_as_expected (fit_function_options_view_test.FitFunctionOptionsViewTest)\n----------------------------------------------------------------------\nAttributeError: &#x27;FitFunctionOptionsView&#x27; object has no attribute &#x27;y&#x27;\n\nThe above exception was the direct cause of the following exception:\n\nTraceback (most recent call last):\n  File &quot;/Users/builder/Jenkins/workspace/main_nightly_deployment_prototype/qt/python/mantidqtinterfaces/test/Muon/fitting_widgets/basic_fitting/fit_function_options_view_test.py&quot;, line 26, in setUp\n    self.view = FitFunctionOptionsView()\n  File &quot;/Users/builder/Jenkins/workspace/main_nightly_deployment_prototype/qt/python/mantidqtinterfaces/mantidqtinterfaces/Muon/GUI/Common/fitting_widgets/basic_fitting/fit_function_options_view.py&quot;, line 48, in __init__\n    self.setupUi(self)\n  File &quot;&lt;string&gt;&quot;, line 71, in setupUi\nSystemError: &lt;built-in function connectSlotsByName&gt; returned a result with an error set\n\n======================================================================\nERROR: test_that_the_function_name_can_be_changed_as_expected (fit_function_options_view_test.FitFunctionOptionsViewTest)\n----------------------------------------------------------------------\nAttributeError: &#x27;FitFunctionOptionsView&#x27; object has no attribute &#x27;y&#x27;\n\nThe above exception was the direct cause of the following exception:\n\nTraceback (most recent call last):\n  File &quot;/Users/builder/Jenkins/workspace/main_nightly_deployment_prototype/qt/python/mantidqtinterfaces/test/Muon/fitting_widgets/basic_fitting/fit_function_options_view_test.py&quot;, line 26, in setUp\n    self.view = FitFunctionOptionsView()\n  File &quot;/Users/builder/Jenkins/workspace/main_nightly_deployment_prototype/qt/python/mantidqtinterfaces/mantidqtinterfaces/Muon/GUI/Common/fitting_widgets/basic_fitting/fit_function_options_view.py&quot;, line 48, in __init__\n    self.setupUi(self)\n  File &quot;&lt;string&gt;&quot;, line 71, in setupUi\nSystemError: &lt;built-in function connectSlotsByName&gt; returned a result with an error set\n\n======================================================================\nERROR: test_that_the_view_has_been_initialized_with_the_raw_data_option_hidden (fit_function_options_view_test.FitFunctionOptionsViewTest)\n----------------------------------------------------------------------\nAttributeError: &#x27;FitFunctionOptionsView&#x27; object has no attribute &#x27;y&#x27;\n\nThe above exception was the direct cause of the following exception:\n\nTraceback (most recent call last):\n  File &quot;/Users/builder/Jenkins/workspace/main_nightly_deployment_prototype/qt/python/mantidqtinterfaces/test/Muon/fitting_widgets/basic_fitting/fit_function_options_view_test.py&quot;, line 26, in setUp\n    self.view = FitFunctionOptionsView()\n  File &quot;/Users/builder/Jenkins/workspace/main_nightly_deployment_prototype/qt/python/mantidqtinterfaces/mantidqtinterfaces/Muon/GUI/Common/fitting_widgets/basic_fitting/fit_function_options_view.py&quot;, line 48, in __init__\n    self.setupUi(self)\n  File &quot;&lt;string&gt;&quot;, line 71, in setupUi\nSystemError: &lt;built-in function connectSlotsByName&gt; returned a result with an error set\n\n======================================================================\nERROR: test_that_the_view_has_been_initialized_with_the_raw_data_option_shown (fit_function_options_view_test.FitFunctionOptionsViewTest)\n----------------------------------------------------------------------\nAttributeError: &#x27;FitFunctionOptionsView&#x27; object has no attribute &#x27;y&#x27;\n\nThe above exception was the direct cause of the following exception:\n\nTraceback (most recent call last):\n  File &quot;/Users/builder/Jenkins/workspace/main_nightly_deployment_prototype/qt/python/mantidqtinterfaces/test/Muon/fitting_widgets/basic_fitting/fit_function_options_view_test.py&quot;, line 26, in setUp\n    self.view = FitFunctionOptionsView()\n  File &quot;/Users/builder/Jenkins/workspace/main_nightly_deployment_prototype/qt/python/mantidqtinterfaces/mantidqtinterfaces/Muon/GUI/Common/fitting_widgets/basic_fitting/fit_function_options_view.py&quot;, line 48, in __init__\n    self.setupUi(self)\n  File &quot;&lt;string&gt;&quot;, line 71, in setupUi\nSystemError: &lt;built-in function connectSlotsByName&gt; returned a result with an error set\n\n======================================================================\nERROR: test_that_update_fit_status_labels_will_display_fit_successful_if_all_fits_are_successful (fit_function_options_view_test.FitFunctionOptionsViewTest)\n----------------------------------------------------------------------\nAttributeError: &#x27;FitFunctionOptionsView&#x27; object has no attribute &#x27;y&#x27;\n\nThe above exception was the direct cause of the following exception:\n\nTraceback (most recent call last):\n  File &quot;/Users/builder/Jenkins/workspace/main_nightly_deployment_prototype/qt/python/mantidqtinterfaces/test/Muon/fitting_widgets/basic_fitting/fit_function_options_view_test.py&quot;, line 26, in setUp\n    self.view = FitFunctionOptionsView()\n  File &quot;/Users/builder/Jenkins/workspace/main_nightly_deployment_prototype/qt/python/mantidqtinterfaces/mantidqtinterfaces/Muon/GUI/Common/fitting_widgets/basic_fitting/fit_function_options_view.py&quot;, line 48, in __init__\n    self.setupUi(self)\n  File &quot;&lt;string&gt;&quot;, line 71, in setupUi\nSystemError: &lt;built-in function connectSlotsByName&gt; returned a result with an error set\n\n======================================================================\nERROR: test_that_update_fit_status_labels_will_display_fits_failed_if_some_of_the_fits_fail (fit_function_options_view_test.FitFunctionOptionsViewTest)\n----------------------------------------------------------------------\nAttributeError: &#x27;FitFunctionOptionsView&#x27; object has no attribute &#x27;y&#x27;\n\nThe above exception was the direct cause of the following exception:\n\nTraceback (most recent call last):\n  File &quot;/Users/builder/Jenkins/workspace/main_nightly_deployment_prototype/qt/python/mantidqtinterfaces/test/Muon/fitting_widgets/basic_fitting/fit_function_options_view_test.py&quot;, line 26, in setUp\n    self.view = FitFunctionOptionsView()\n  File &quot;/Users/builder/Jenkins/workspace/main_nightly_deployment_prototype/qt/python/mantidqtinterfaces/mantidqtinterfaces/Muon/GUI/Common/fitting_widgets/basic_fitting/fit_function_options_view.py&quot;, line 48, in __init__\n    self.setupUi(self)\n  File &quot;&lt;string&gt;&quot;, line 71, in setupUi\nSystemError: &lt;built-in function connectSlotsByName&gt; returned a result with an error set\n\n======================================================================\nERROR: test_that_update_fit_status_labels_will_display_no_fit_if_the_success_list_is_empty (fit_function_options_view_test.FitFunctionOptionsViewTest)\n----------------------------------------------------------------------\nAttributeError: &#x27;FitFunctionOptionsView&#x27; object has no attribute &#x27;y&#x27;\n\nThe above exception was the direct cause of the following exception:\n\nTraceback (most recent call last):\n  File &quot;/Users/builder/Jenkins/workspace/main_nightly_deployment_prototype/qt/python/mantidqtinterfaces/test/Muon/fitting_widgets/basic_fitting/fit_function_options_view_test.py&quot;, line 26, in setUp\n    self.view = FitFunctionOptionsView()\n  File &quot;/Users/builder/Jenkins/workspace/main_nightly_deployment_prototype/qt/python/mantidqtinterfaces/mantidqtinterfaces/Muon/GUI/Common/fitting_widgets/basic_fitting/fit_function_options_view.py&quot;, line 48, in __init__\n    self.setupUi(self)\n  File &quot;&lt;string&gt;&quot;, line 71, in setupUi\nSystemError: &lt;built-in function connectSlotsByName&gt; returned a result with an error set\n\n======================================================================\nERROR: test_that_update_function_browser_parameters_will_clear_the_function_if_the_function_provided_is_none (fit_function_options_view_test.FitFunctionOptionsViewTest)\n----------------------------------------------------------------------\nAttributeError: &#x27;FitFunctionOptionsView&#x27; object has no attribute &#x27;y&#x27;\n\nThe above exception was the direct cause of the following exception:\n\nTraceback (most recent call last):\n  File &quot;/Users/builder/Jenkins/workspace/main_nightly_deployment_prototype/qt/python/mantidqtinterfaces/test/Muon/fitting_widgets/basic_fitting/fit_function_options_view_test.py&quot;, line 26, in setUp\n    self.view = FitFunctionOptionsView()\n  File &quot;/Users/builder/Jenkins/workspace/main_nightly_deployment_prototype/qt/python/mantidqtinterfaces/mantidqtinterfaces/Muon/GUI/Common/fitting_widgets/basic_fitting/fit_function_options_view.py&quot;, line 48, in __init__\n    self.setupUi(self)\n  File &quot;&lt;string&gt;&quot;, line 71, in setupUi\nSystemError: &lt;built-in function connectSlotsByName&gt; returned a result with an error set\n\n======================================================================\nERROR: test_that_update_function_browser_parameters_will_set_the_function_if_in_simultaneous_mode (fit_function_options_view_test.FitFunctionOptionsViewTest)\n----------------------------------------------------------------------\nAttributeError: &#x27;FitFunctionOptionsView&#x27; object has no attribute &#x27;y&#x27;\n\nThe above exception was the direct cause of the following exception:\n\nTraceback (most recent call last):\n  File &quot;/Users/builder/Jenkins/workspace/main_nightly_deployment_prototype/qt/python/mantidqtinterfaces/test/Muon/fitting_widgets/basic_fitting/fit_function_options_view_test.py&quot;, line 26, in setUp\n    self.view = FitFunctionOptionsView()\n  File &quot;/Users/builder/Jenkins/workspace/main_nightly_deployment_prototype/qt/python/mantidqtinterfaces/mantidqtinterfaces/Muon/GUI/Common/fitting_widgets/basic_fitting/fit_function_options_view.py&quot;, line 48, in __init__\n    self.setupUi(self)\n  File &quot;&lt;string&gt;&quot;, line 71, in setupUi\nSystemError: &lt;built-in function connectSlotsByName&gt; returned a result with an error set\n\n======================================================================\nERROR: test_that_update_function_browser_parameters_will_update_the_parameters_of_the_function_for_single_fit (fit_function_options_view_test.FitFunctionOptionsViewTest)\n----------------------------------------------------------------------\nAttributeError: &#x27;FitFunctionOptionsView&#x27; object has no attribute &#x27;y&#x27;\n\nThe above exception was the direct cause of the following exception:\n\nTraceback (most recent call last):\n  File &quot;/Users/builder/Jenkins/workspace/main_nightly_deployment_prototype/qt/python/mantidqtinterfaces/test/Muon/fitting_widgets/basic_fitting/fit_function_options_view_test.py&quot;, line 26, in setUp\n    self.view = FitFunctionOptionsView()\n  File &quot;/Users/builder/Jenkins/workspace/main_nightly_deployment_prototype/qt/python/mantidqtinterfaces/mantidqtinterfaces/Muon/GUI/Common/fitting_widgets/basic_fitting/fit_function_options_view.py&quot;, line 48, in __init__\n    self.setupUi(self)\n  File &quot;&lt;string&gt;&quot;, line 71, in setupUi\nSystemError: &lt;built-in function connectSlotsByName&gt; returned a result with an error set\n\n----------------------------------------------------------------------\nRan 19 tests in 1.152s\n\nFAILED (errors=19)\n\n          Start 2179: python.MuonQt5.fit_function_options_view_test.fit_function_options_view_test\n"
            }
        }
    ]
}