{
    "data": [
        {
            "test_name": "python.MuonQt5.general_fitting_view_test.general_fitting_view_test",
            "latest_failed_build": "620",
            "agent_name": "Mac",
            "last_failed_outcome": "Flake",
            "pipeline_name": "pull_requests-conda-osx",
            "problem_count": 1,
            "past_outcome": {
                "build_keys": [
                    "642",
                    "641",
                    "640",
                    "639",
                    "638",
                    "637",
                    "636",
                    "635",
                    "634",
                    "633",
                    "632",
                    "631",
                    "630",
                    "629",
                    "628",
                    "627",
                    "626",
                    "625",
                    "624",
                    "623",
                    "622",
                    "621",
                    "620",
                    "619",
                    "618",
                    "617",
                    "616",
                    "615",
                    "614",
                    "613"
                ],
                "past_outcome_list": [
                    "Passed",
                    "Passed",
                    "Passed",
                    "Passed",
                    "Passed",
                    "Passed",
                    "Passed",
                    "Passed",
                    "Passed",
                    "Passed",
                    "Passed",
                    "Passed",
                    "Passed",
                    "Passed",
                    "Passed",
                    "Passed",
                    "Passed",
                    "Passed",
                    "Passed",
                    "Passed",
                    "Passed",
                    "Passed",
                    "Flake",
                    "Passed",
                    "None",
                    "None",
                    "None",
                    "None",
                    "None",
                    "None"
                ]
            },
            "last_stack_traces": {
                "test_name": "python.MuonQt5.general_fitting_view_test.general_fitting_view_test",
                "build": "620",
                "agent_name": "Mac",
                "trial": 1,
                "outcome": "Failed",
                "test_time": "8.91",
                "stacktrace": "FrameworkManager-[Notice] Welcome to Mantid 6.5.20221115.1527\nFrameworkManager-[Notice] Please cite: http://dx.doi.org/10.1016/j.nima.2014.07.029 and this release: http://dx.doi.org/10.5286/Software/Mantid\nEEEEEEEEEEEE\n======================================================================\nERROR: test_that_current_dataset_index_will_return_none_when_there_is_nothing_selected_in_the_combobox (general_fitting_view_test.GeneralFittingViewTest)\n----------------------------------------------------------------------\nAttributeError: &#x27;GeneralFittingView&#x27; object has no attribute &#x27;y&#x27;\n\nThe above exception was the direct cause of the following exception:\n\nTraceback (most recent call last):\n  File &quot;/Users/builder/Jenkins/workspace/pull_requests-conda-osx/qt/python/mantidqtinterfaces/test/Muon/fitting_widgets/general_fitting/general_fitting_view_test.py&quot;, line 20, in setUp\n    self.view = GeneralFittingView()\n  File &quot;/Users/builder/Jenkins/workspace/pull_requests-conda-osx/qt/python/mantidqtinterfaces/mantidqtinterfaces/Muon/GUI/Common/fitting_widgets/general_fitting/general_fitting_view.py&quot;, line 25, in __init__\n    super(GeneralFittingView, self).__init__(parent)\n  File &quot;/Users/builder/Jenkins/workspace/pull_requests-conda-osx/qt/python/mantidqtinterfaces/mantidqtinterfaces/Muon/GUI/Common/fitting_widgets/basic_fitting/basic_fitting_view.py&quot;, line 29, in __init__\n    self.setupUi(self)\n  File &quot;&lt;string&gt;&quot;, line 31, in setupUi\nSystemError: &lt;built-in function connectSlotsByName&gt; returned a result with an error set\n\n======================================================================\nERROR: test_that_current_dataset_index_will_return_the_expected_dataset_index (general_fitting_view_test.GeneralFittingViewTest)\n----------------------------------------------------------------------\nAttributeError: &#x27;GeneralFittingView&#x27; object has no attribute &#x27;y&#x27;\n\nThe above exception was the direct cause of the following exception:\n\nTraceback (most recent call last):\n  File &quot;/Users/builder/Jenkins/workspace/pull_requests-conda-osx/qt/python/mantidqtinterfaces/test/Muon/fitting_widgets/general_fitting/general_fitting_view_test.py&quot;, line 20, in setUp\n    self.view = GeneralFittingView()\n  File &quot;/Users/builder/Jenkins/workspace/pull_requests-conda-osx/qt/python/mantidqtinterfaces/mantidqtinterfaces/Muon/GUI/Common/fitting_widgets/general_fitting/general_fitting_view.py&quot;, line 25, in __init__\n    super(GeneralFittingView, self).__init__(parent)\n  File &quot;/Users/builder/Jenkins/workspace/pull_requests-conda-osx/qt/python/mantidqtinterfaces/mantidqtinterfaces/Muon/GUI/Common/fitting_widgets/basic_fitting/basic_fitting_view.py&quot;, line 29, in __init__\n    self.setupUi(self)\n  File &quot;&lt;string&gt;&quot;, line 31, in setupUi\nSystemError: &lt;built-in function connectSlotsByName&gt; returned a result with an error set\n\n======================================================================\nERROR: test_that_number_of_datasets_will_return_the_expected_number_of_datasets (general_fitting_view_test.GeneralFittingViewTest)\n----------------------------------------------------------------------\nAttributeError: &#x27;GeneralFittingView&#x27; object has no attribute &#x27;y&#x27;\n\nThe above exception was the direct cause of the following exception:\n\nTraceback (most recent call last):\n  File &quot;/Users/builder/Jenkins/workspace/pull_requests-conda-osx/qt/python/mantidqtinterfaces/test/Muon/fitting_widgets/general_fitting/general_fitting_view_test.py&quot;, line 20, in setUp\n    self.view = GeneralFittingView()\n  File &quot;/Users/builder/Jenkins/workspace/pull_requests-conda-osx/qt/python/mantidqtinterfaces/mantidqtinterfaces/Muon/GUI/Common/fitting_widgets/general_fitting/general_fitting_view.py&quot;, line 25, in __init__\n    super(GeneralFittingView, self).__init__(parent)\n  File &quot;/Users/builder/Jenkins/workspace/pull_requests-conda-osx/qt/python/mantidqtinterfaces/mantidqtinterfaces/Muon/GUI/Common/fitting_widgets/basic_fitting/basic_fitting_view.py&quot;, line 29, in __init__\n    self.setupUi(self)\n  File &quot;&lt;string&gt;&quot;, line 31, in setupUi\nSystemError: &lt;built-in function connectSlotsByName&gt; returned a result with an error set\n\n======================================================================\nERROR: test_that_setup_fit_by_specifier_will_add_fit_specifiers_to_the_relevant_checkbox (general_fitting_view_test.GeneralFittingViewTest)\n----------------------------------------------------------------------\nAttributeError: &#x27;GeneralFittingView&#x27; object has no attribute &#x27;y&#x27;\n\nThe above exception was the direct cause of the following exception:\n\nTraceback (most recent call last):\n  File &quot;/Users/builder/Jenkins/workspace/pull_requests-conda-osx/qt/python/mantidqtinterfaces/test/Muon/fitting_widgets/general_fitting/general_fitting_view_test.py&quot;, line 20, in setUp\n    self.view = GeneralFittingView()\n  File &quot;/Users/builder/Jenkins/workspace/pull_requests-conda-osx/qt/python/mantidqtinterfaces/mantidqtinterfaces/Muon/GUI/Common/fitting_widgets/general_fitting/general_fitting_view.py&quot;, line 25, in __init__\n    super(GeneralFittingView, self).__init__(parent)\n  File &quot;/Users/builder/Jenkins/workspace/pull_requests-conda-osx/qt/python/mantidqtinterfaces/mantidqtinterfaces/Muon/GUI/Common/fitting_widgets/basic_fitting/basic_fitting_view.py&quot;, line 29, in __init__\n    self.setupUi(self)\n  File &quot;&lt;string&gt;&quot;, line 31, in setupUi\nSystemError: &lt;built-in function connectSlotsByName&gt; returned a result with an error set\n\n======================================================================\nERROR: test_that_switch_to_simultaneous_will_change_the_relevant_label (general_fitting_view_test.GeneralFittingViewTest)\n----------------------------------------------------------------------\nAttributeError: &#x27;GeneralFittingView&#x27; object has no attribute &#x27;y&#x27;\n\nThe above exception was the direct cause of the following exception:\n\nTraceback (most recent call last):\n  File &quot;/Users/builder/Jenkins/workspace/pull_requests-conda-osx/qt/python/mantidqtinterfaces/test/Muon/fitting_widgets/general_fitting/general_fitting_view_test.py&quot;, line 20, in setUp\n    self.view = GeneralFittingView()\n  File &quot;/Users/builder/Jenkins/workspace/pull_requests-conda-osx/qt/python/mantidqtinterfaces/mantidqtinterfaces/Muon/GUI/Common/fitting_widgets/general_fitting/general_fitting_view.py&quot;, line 25, in __init__\n    super(GeneralFittingView, self).__init__(parent)\n  File &quot;/Users/builder/Jenkins/workspace/pull_requests-conda-osx/qt/python/mantidqtinterfaces/mantidqtinterfaces/Muon/GUI/Common/fitting_widgets/basic_fitting/basic_fitting_view.py&quot;, line 29, in __init__\n    self.setupUi(self)\n  File &quot;&lt;string&gt;&quot;, line 31, in setupUi\nSystemError: &lt;built-in function connectSlotsByName&gt; returned a result with an error set\n\n======================================================================\nERROR: test_that_switch_to_single_will_change_the_relevant_label (general_fitting_view_test.GeneralFittingViewTest)\n----------------------------------------------------------------------\nAttributeError: &#x27;GeneralFittingView&#x27; object has no attribute &#x27;y&#x27;\n\nThe above exception was the direct cause of the following exception:\n\nTraceback (most recent call last):\n  File &quot;/Users/builder/Jenkins/workspace/pull_requests-conda-osx/qt/python/mantidqtinterfaces/test/Muon/fitting_widgets/general_fitting/general_fitting_view_test.py&quot;, line 20, in setUp\n    self.view = GeneralFittingView()\n  File &quot;/Users/builder/Jenkins/workspace/pull_requests-conda-osx/qt/python/mantidqtinterfaces/mantidqtinterfaces/Muon/GUI/Common/fitting_widgets/general_fitting/general_fitting_view.py&quot;, line 25, in __init__\n    super(GeneralFittingView, self).__init__(parent)\n  File &quot;/Users/builder/Jenkins/workspace/pull_requests-conda-osx/qt/python/mantidqtinterfaces/mantidqtinterfaces/Muon/GUI/Common/fitting_widgets/basic_fitting/basic_fitting_view.py&quot;, line 29, in __init__\n    self.setupUi(self)\n  File &quot;&lt;string&gt;&quot;, line 31, in setupUi\nSystemError: &lt;built-in function connectSlotsByName&gt; returned a result with an error set\n\n======================================================================\nERROR: test_that_the_current_dataset_name_can_be_set_as_expected (general_fitting_view_test.GeneralFittingViewTest)\n----------------------------------------------------------------------\nAttributeError: &#x27;GeneralFittingView&#x27; object has no attribute &#x27;y&#x27;\n\nThe above exception was the direct cause of the following exception:\n\nTraceback (most recent call last):\n  File &quot;/Users/builder/Jenkins/workspace/pull_requests-conda-osx/qt/python/mantidqtinterfaces/test/Muon/fitting_widgets/general_fitting/general_fitting_view_test.py&quot;, line 20, in setUp\n    self.view = GeneralFittingView()\n  File &quot;/Users/builder/Jenkins/workspace/pull_requests-conda-osx/qt/python/mantidqtinterfaces/mantidqtinterfaces/Muon/GUI/Common/fitting_widgets/general_fitting/general_fitting_view.py&quot;, line 25, in __init__\n    super(GeneralFittingView, self).__init__(parent)\n  File &quot;/Users/builder/Jenkins/workspace/pull_requests-conda-osx/qt/python/mantidqtinterfaces/mantidqtinterfaces/Muon/GUI/Common/fitting_widgets/basic_fitting/basic_fitting_view.py&quot;, line 29, in __init__\n    self.setupUi(self)\n  File &quot;&lt;string&gt;&quot;, line 31, in setupUi\nSystemError: &lt;built-in function connectSlotsByName&gt; returned a result with an error set\n\n======================================================================\nERROR: test_that_the_current_dataset_name_will_not_change_the_selected_dataset_if_the_provided_dataset_does_not_exist (general_fitting_view_test.GeneralFittingViewTest)\n----------------------------------------------------------------------\nAttributeError: &#x27;GeneralFittingView&#x27; object has no attribute &#x27;y&#x27;\n\nThe above exception was the direct cause of the following exception:\n\nTraceback (most recent call last):\n  File &quot;/Users/builder/Jenkins/workspace/pull_requests-conda-osx/qt/python/mantidqtinterfaces/test/Muon/fitting_widgets/general_fitting/general_fitting_view_test.py&quot;, line 20, in setUp\n    self.view = GeneralFittingView()\n  File &quot;/Users/builder/Jenkins/workspace/pull_requests-conda-osx/qt/python/mantidqtinterfaces/mantidqtinterfaces/Muon/GUI/Common/fitting_widgets/general_fitting/general_fitting_view.py&quot;, line 25, in __init__\n    super(GeneralFittingView, self).__init__(parent)\n  File &quot;/Users/builder/Jenkins/workspace/pull_requests-conda-osx/qt/python/mantidqtinterfaces/mantidqtinterfaces/Muon/GUI/Common/fitting_widgets/basic_fitting/basic_fitting_view.py&quot;, line 29, in __init__\n    self.setupUi(self)\n  File &quot;&lt;string&gt;&quot;, line 31, in setupUi\nSystemError: &lt;built-in function connectSlotsByName&gt; returned a result with an error set\n\n======================================================================\nERROR: test_that_the_simultaneous_fit_by_can_be_set_as_expected (general_fitting_view_test.GeneralFittingViewTest)\n----------------------------------------------------------------------\nAttributeError: &#x27;GeneralFittingView&#x27; object has no attribute &#x27;y&#x27;\n\nThe above exception was the direct cause of the following exception:\n\nTraceback (most recent call last):\n  File &quot;/Users/builder/Jenkins/workspace/pull_requests-conda-osx/qt/python/mantidqtinterfaces/test/Muon/fitting_widgets/general_fitting/general_fitting_view_test.py&quot;, line 20, in setUp\n    self.view = GeneralFittingView()\n  File &quot;/Users/builder/Jenkins/workspace/pull_requests-conda-osx/qt/python/mantidqtinterfaces/mantidqtinterfaces/Muon/GUI/Common/fitting_widgets/general_fitting/general_fitting_view.py&quot;, line 25, in __init__\n    super(GeneralFittingView, self).__init__(parent)\n  File &quot;/Users/builder/Jenkins/workspace/pull_requests-conda-osx/qt/python/mantidqtinterfaces/mantidqtinterfaces/Muon/GUI/Common/fitting_widgets/basic_fitting/basic_fitting_view.py&quot;, line 29, in __init__\n    self.setupUi(self)\n  File &quot;&lt;string&gt;&quot;, line 31, in setupUi\nSystemError: &lt;built-in function connectSlotsByName&gt; returned a result with an error set\n\n======================================================================\nERROR: test_that_the_view_can_be_initialized_without_an_error (general_fitting_view_test.GeneralFittingViewTest)\n----------------------------------------------------------------------\nAttributeError: &#x27;GeneralFittingView&#x27; object has no attribute &#x27;y&#x27;\n\nThe above exception was the direct cause of the following exception:\n\nTraceback (most recent call last):\n  File &quot;/Users/builder/Jenkins/workspace/pull_requests-conda-osx/qt/python/mantidqtinterfaces/test/Muon/fitting_widgets/general_fitting/general_fitting_view_test.py&quot;, line 20, in setUp\n    self.view = GeneralFittingView()\n  File &quot;/Users/builder/Jenkins/workspace/pull_requests-conda-osx/qt/python/mantidqtinterfaces/mantidqtinterfaces/Muon/GUI/Common/fitting_widgets/general_fitting/general_fitting_view.py&quot;, line 25, in __init__\n    super(GeneralFittingView, self).__init__(parent)\n  File &quot;/Users/builder/Jenkins/workspace/pull_requests-conda-osx/qt/python/mantidqtinterfaces/mantidqtinterfaces/Muon/GUI/Common/fitting_widgets/basic_fitting/basic_fitting_view.py&quot;, line 29, in __init__\n    self.setupUi(self)\n  File &quot;&lt;string&gt;&quot;, line 31, in setupUi\nSystemError: &lt;built-in function connectSlotsByName&gt; returned a result with an error set\n\n======================================================================\nERROR: test_that_update_dataset_name_combo_box_will_select_the_previously_selected_item_if_it_still_exists (general_fitting_view_test.GeneralFittingViewTest)\n----------------------------------------------------------------------\nAttributeError: &#x27;GeneralFittingView&#x27; object has no attribute &#x27;y&#x27;\n\nThe above exception was the direct cause of the following exception:\n\nTraceback (most recent call last):\n  File &quot;/Users/builder/Jenkins/workspace/pull_requests-conda-osx/qt/python/mantidqtinterfaces/test/Muon/fitting_widgets/general_fitting/general_fitting_view_test.py&quot;, line 20, in setUp\n    self.view = GeneralFittingView()\n  File &quot;/Users/builder/Jenkins/workspace/pull_requests-conda-osx/qt/python/mantidqtinterfaces/mantidqtinterfaces/Muon/GUI/Common/fitting_widgets/general_fitting/general_fitting_view.py&quot;, line 25, in __init__\n    super(GeneralFittingView, self).__init__(parent)\n  File &quot;/Users/builder/Jenkins/workspace/pull_requests-conda-osx/qt/python/mantidqtinterfaces/mantidqtinterfaces/Muon/GUI/Common/fitting_widgets/basic_fitting/basic_fitting_view.py&quot;, line 29, in __init__\n    self.setupUi(self)\n  File &quot;&lt;string&gt;&quot;, line 31, in setupUi\nSystemError: &lt;built-in function connectSlotsByName&gt; returned a result with an error set\n\n======================================================================\nERROR: test_that_update_dataset_name_combo_box_will_set_the_names_in_the_dataset_name_combobox (general_fitting_view_test.GeneralFittingViewTest)\n----------------------------------------------------------------------\nAttributeError: &#x27;GeneralFittingView&#x27; object has no attribute &#x27;y&#x27;\n\nThe above exception was the direct cause of the following exception:\n\nTraceback (most recent call last):\n  File &quot;/Users/builder/Jenkins/workspace/pull_requests-conda-osx/qt/python/mantidqtinterfaces/test/Muon/fitting_widgets/general_fitting/general_fitting_view_test.py&quot;, line 20, in setUp\n    self.view = GeneralFittingView()\n  File &quot;/Users/builder/Jenkins/workspace/pull_requests-conda-osx/qt/python/mantidqtinterfaces/mantidqtinterfaces/Muon/GUI/Common/fitting_widgets/general_fitting/general_fitting_view.py&quot;, line 25, in __init__\n    super(GeneralFittingView, self).__init__(parent)\n  File &quot;/Users/builder/Jenkins/workspace/pull_requests-conda-osx/qt/python/mantidqtinterfaces/mantidqtinterfaces/Muon/GUI/Common/fitting_widgets/basic_fitting/basic_fitting_view.py&quot;, line 29, in __init__\n    self.setupUi(self)\n  File &quot;&lt;string&gt;&quot;, line 31, in setupUi\nSystemError: &lt;built-in function connectSlotsByName&gt; returned a result with an error set\n\n----------------------------------------------------------------------\nRan 12 tests in 0.660s\n\nFAILED (errors=12)\n\n          Start 2183: python.MuonQt5.general_fitting_view_test.general_fitting_view_test\n"
            }
        }
    ]
}