{
    "data": [
        {
            "test_name": "python.MuonQt5.fit_function_options_view_test.fit_function_options_view_test",
            "latest_failed_build": "2277",
            "agent_name": "Linux",
            "last_failed_outcome": "Flake",
            "pipeline_name": "pull_requests-conda-linux",
            "problem_count": 1,
            "past_outcome": {
                "build_keys": [
                    "2279",
                    "2278",
                    "2277",
                    "2276",
                    "2275",
                    "2274",
                    "2273",
                    "2272",
                    "2271",
                    "2270",
                    "2269",
                    "2268",
                    "2267",
                    "2266",
                    "2265",
                    "2264",
                    "2263",
                    "2262",
                    "2261",
                    "2260",
                    "2259",
                    "2258",
                    "2257",
                    "2256",
                    "2255",
                    "2254",
                    "2253",
                    "2252",
                    "2251",
                    "2250"
                ],
                "past_outcome_list": [
                    "None",
                    "Passed",
                    "Flake",
                    "Passed",
                    "Passed",
                    "Passed",
                    "Passed",
                    "Passed",
                    "Passed",
                    "Passed",
                    "Passed",
                    "Passed",
                    "Passed",
                    "Passed",
                    "Passed",
                    "Passed",
                    "Passed",
                    "Passed",
                    "Passed",
                    "Passed",
                    "Passed",
                    "Passed",
                    "None",
                    "Passed",
                    "Passed",
                    "Passed",
                    "None",
                    "None",
                    "None",
                    "None"
                ]
            },
            "last_stack_traces": {
                "test_name": "python.MuonQt5.fit_function_options_view_test.fit_function_options_view_test",
                "build": "2277",
                "agent_name": "Linux",
                "trial": 1,
                "outcome": "Failed",
                "test_time": "4.99",
                "stacktrace": "FrameworkManager-[Notice] Welcome to Mantid 6.5.20221218.1722\nFrameworkManager-[Notice] Please cite: http://dx.doi.org/10.1016/j.nima.2014.07.029 and this release: http://dx.doi.org/10.5286/Software/Mantid\nQStandardPaths: XDG_RUNTIME_DIR not set, defaulting to &#x27;/tmp/runtime-abc&#x27;\nlibEGL warning: DRI2: failed to open swrast (search paths /usr/lib64/dri)\nlibEGL warning: DRI2: failed to open swrast (search paths /usr/lib64/dri)\nlibEGL warning: DRI2: failed to open swrast (search paths /usr/lib64/dri)\nlibEGL warning: DRI2: failed to open swrast (search paths /usr/lib64/dri)\nQXcbIntegration: Cannot create platform OpenGL context, neither GLX nor EGL are enabled\nEEEEEEEEEEEEEEEEEEE\n======================================================================\nERROR: test_that_clear_fit_status_will_clear_the_fit_status_and_chi_squared (fit_function_options_view_test.FitFunctionOptionsViewTest)\n----------------------------------------------------------------------\nAttributeError: &#x27;FitFunctionOptionsView&#x27; object has no attribute &#x27;y&#x27;\n\nThe above exception was the direct cause of the following exception:\n\nTraceback (most recent call last):\n  File &quot;/jenkins_workdir/workspace/pull_requests-conda-linux/qt/python/mantidqtinterfaces/test/Muon/fitting_widgets/basic_fitting/fit_function_options_view_test.py&quot;, line 26, in setUp\n    self.view = FitFunctionOptionsView()\n  File &quot;/jenkins_workdir/workspace/pull_requests-conda-linux/qt/python/mantidqtinterfaces/mantidqtinterfaces/Muon/GUI/Common/fitting_widgets/basic_fitting/fit_function_options_view.py&quot;, line 48, in __init__\n    self.setupUi(self)\n  File &quot;&lt;string&gt;&quot;, line 71, in setupUi\nSystemError: &lt;built-in function connectSlotsByName&gt; returned a result with an error set\n\n======================================================================\nERROR: test_that_it_is_possible_to_set_the_end_x_to_a_different_value (fit_function_options_view_test.FitFunctionOptionsViewTest)\n----------------------------------------------------------------------\nAttributeError: &#x27;FitFunctionOptionsView&#x27; object has no attribute &#x27;y&#x27;\n\nThe above exception was the direct cause of the following exception:\n\nTraceback (most recent call last):\n  File &quot;/jenkins_workdir/workspace/pull_requests-conda-linux/qt/python/mantidqtinterfaces/test/Muon/fitting_widgets/basic_fitting/fit_function_options_view_test.py&quot;, line 26, in setUp\n    self.view = FitFunctionOptionsView()\n  File &quot;/jenkins_workdir/workspace/pull_requests-conda-linux/qt/python/mantidqtinterfaces/mantidqtinterfaces/Muon/GUI/Common/fitting_widgets/basic_fitting/fit_function_options_view.py&quot;, line 48, in __init__\n    self.setupUi(self)\n  File &quot;&lt;string&gt;&quot;, line 71, in setupUi\nSystemError: &lt;built-in function connectSlotsByName&gt; returned a result with an error set\n\n======================================================================\nERROR: test_that_it_is_possible_to_set_the_start_x_to_a_different_value (fit_function_options_view_test.FitFunctionOptionsViewTest)\n----------------------------------------------------------------------\nAttributeError: &#x27;FitFunctionOptionsView&#x27; object has no attribute &#x27;y&#x27;\n\nThe above exception was the direct cause of the following exception:\n\nTraceback (most recent call last):\n  File &quot;/jenkins_workdir/workspace/pull_requests-conda-linux/qt/python/mantidqtinterfaces/test/Muon/fitting_widgets/basic_fitting/fit_function_options_view_test.py&quot;, line 26, in setUp\n    self.view = FitFunctionOptionsView()\n  File &quot;/jenkins_workdir/workspace/pull_requests-conda-linux/qt/python/mantidqtinterfaces/mantidqtinterfaces/Muon/GUI/Common/fitting_widgets/basic_fitting/fit_function_options_view.py&quot;, line 48, in __init__\n    self.setupUi(self)\n  File &quot;&lt;string&gt;&quot;, line 71, in setupUi\nSystemError: &lt;built-in function connectSlotsByName&gt; returned a result with an error set\n\n======================================================================\nERROR: test_that_set_covariance_button_enabled_can_disable_the_covariance_button (fit_function_options_view_test.FitFunctionOptionsViewTest)\n----------------------------------------------------------------------\nAttributeError: &#x27;FitFunctionOptionsView&#x27; object has no attribute &#x27;y&#x27;\n\nThe above exception was the direct cause of the following exception:\n\nTraceback (most recent call last):\n  File &quot;/jenkins_workdir/workspace/pull_requests-conda-linux/qt/python/mantidqtinterfaces/test/Muon/fitting_widgets/basic_fitting/fit_function_options_view_test.py&quot;, line 26, in setUp\n    self.view = FitFunctionOptionsView()\n  File &quot;/jenkins_workdir/workspace/pull_requests-conda-linux/qt/python/mantidqtinterfaces/mantidqtinterfaces/Muon/GUI/Common/fitting_widgets/basic_fitting/fit_function_options_view.py&quot;, line 48, in __init__\n    self.setupUi(self)\n  File &quot;&lt;string&gt;&quot;, line 71, in setupUi\nSystemError: &lt;built-in function connectSlotsByName&gt; returned a result with an error set\n\n======================================================================\nERROR: test_that_set_covariance_button_enabled_can_enable_the_covariance_button (fit_function_options_view_test.FitFunctionOptionsViewTest)\n----------------------------------------------------------------------\nAttributeError: &#x27;FitFunctionOptionsView&#x27; object has no attribute &#x27;y&#x27;\n\nThe above exception was the direct cause of the following exception:\n\nTraceback (most recent call last):\n  File &quot;/jenkins_workdir/workspace/pull_requests-conda-linux/qt/python/mantidqtinterfaces/test/Muon/fitting_widgets/basic_fitting/fit_function_options_view_test.py&quot;, line 26, in setUp\n    self.view = FitFunctionOptionsView()\n  File &quot;/jenkins_workdir/workspace/pull_requests-conda-linux/qt/python/mantidqtinterfaces/mantidqtinterfaces/Muon/GUI/Common/fitting_widgets/basic_fitting/fit_function_options_view.py&quot;, line 48, in __init__\n    self.setupUi(self)\n  File &quot;&lt;string&gt;&quot;, line 71, in setupUi\nSystemError: &lt;built-in function connectSlotsByName&gt; returned a result with an error set\n\n======================================================================\nERROR: test_that_set_current_dataset_index_will_set_the_current_dataset_index_in_the_function_browser (fit_function_options_view_test.FitFunctionOptionsViewTest)\n----------------------------------------------------------------------\nAttributeError: &#x27;FitFunctionOptionsView&#x27; object has no attribute &#x27;y&#x27;\n\nThe above exception was the direct cause of the following exception:\n\nTraceback (most recent call last):\n  File &quot;/jenkins_workdir/workspace/pull_requests-conda-linux/qt/python/mantidqtinterfaces/test/Muon/fitting_widgets/basic_fitting/fit_function_options_view_test.py&quot;, line 26, in setUp\n    self.view = FitFunctionOptionsView()\n  File &quot;/jenkins_workdir/workspace/pull_requests-conda-linux/qt/python/mantidqtinterfaces/mantidqtinterfaces/Muon/GUI/Common/fitting_widgets/basic_fitting/fit_function_options_view.py&quot;, line 48, in __init__\n    self.setupUi(self)\n  File &quot;&lt;string&gt;&quot;, line 71, in setupUi\nSystemError: &lt;built-in function connectSlotsByName&gt; returned a result with an error set\n\n======================================================================\nERROR: test_that_set_datasets_in_function_browser_will_set_the_datasets_in_the_function_browser (fit_function_options_view_test.FitFunctionOptionsViewTest)\n----------------------------------------------------------------------\nAttributeError: &#x27;FitFunctionOptionsView&#x27; object has no attribute &#x27;y&#x27;\n\nThe above exception was the direct cause of the following exception:\n\nTraceback (most recent call last):\n  File &quot;/jenkins_workdir/workspace/pull_requests-conda-linux/qt/python/mantidqtinterfaces/test/Muon/fitting_widgets/basic_fitting/fit_function_options_view_test.py&quot;, line 26, in setUp\n    self.view = FitFunctionOptionsView()\n  File &quot;/jenkins_workdir/workspace/pull_requests-conda-linux/qt/python/mantidqtinterfaces/mantidqtinterfaces/Muon/GUI/Common/fitting_widgets/basic_fitting/fit_function_options_view.py&quot;, line 48, in __init__\n    self.setupUi(self)\n  File &quot;&lt;string&gt;&quot;, line 71, in setupUi\nSystemError: &lt;built-in function connectSlotsByName&gt; returned a result with an error set\n\n======================================================================\nERROR: test_that_set_fit_function_will_set_the_function_in_the_browser (fit_function_options_view_test.FitFunctionOptionsViewTest)\n----------------------------------------------------------------------\nAttributeError: &#x27;FitFunctionOptionsView&#x27; object has no attribute &#x27;y&#x27;\n\nThe above exception was the direct cause of the following exception:\n\nTraceback (most recent call last):\n  File &quot;/jenkins_workdir/workspace/pull_requests-conda-linux/qt/python/mantidqtinterfaces/test/Muon/fitting_widgets/basic_fitting/fit_function_options_view_test.py&quot;, line 26, in setUp\n    self.view = FitFunctionOptionsView()\n  File &quot;/jenkins_workdir/workspace/pull_requests-conda-linux/qt/python/mantidqtinterfaces/mantidqtinterfaces/Muon/GUI/Common/fitting_widgets/basic_fitting/fit_function_options_view.py&quot;, line 48, in __init__\n    self.setupUi(self)\n  File &quot;&lt;string&gt;&quot;, line 71, in setupUi\nSystemError: &lt;built-in function connectSlotsByName&gt; returned a result with an error set\n\n======================================================================\nERROR: test_that_show_normalised_covariance_matrix_will_not_raise_an_error (fit_function_options_view_test.FitFunctionOptionsViewTest)\n----------------------------------------------------------------------\nAttributeError: &#x27;FitFunctionOptionsView&#x27; object has no attribute &#x27;y&#x27;\n\nThe above exception was the direct cause of the following exception:\n\nTraceback (most recent call last):\n  File &quot;/jenkins_workdir/workspace/pull_requests-conda-linux/qt/python/mantidqtinterfaces/test/Muon/fitting_widgets/basic_fitting/fit_function_options_view_test.py&quot;, line 26, in setUp\n    self.view = FitFunctionOptionsView()\n  File &quot;/jenkins_workdir/workspace/pull_requests-conda-linux/qt/python/mantidqtinterfaces/mantidqtinterfaces/Muon/GUI/Common/fitting_widgets/basic_fitting/fit_function_options_view.py&quot;, line 48, in __init__\n    self.setupUi(self)\n  File &quot;&lt;string&gt;&quot;, line 71, in setupUi\nSystemError: &lt;built-in function connectSlotsByName&gt; returned a result with an error set\n\n======================================================================\nERROR: test_that_the_fit_to_raw_checkbox_value_can_be_changed_as_expected (fit_function_options_view_test.FitFunctionOptionsViewTest)\n----------------------------------------------------------------------\nAttributeError: &#x27;FitFunctionOptionsView&#x27; object has no attribute &#x27;y&#x27;\n\nThe above exception was the direct cause of the following exception:\n\nTraceback (most recent call last):\n  File &quot;/jenkins_workdir/workspace/pull_requests-conda-linux/qt/python/mantidqtinterfaces/test/Muon/fitting_widgets/basic_fitting/fit_function_options_view_test.py&quot;, line 26, in setUp\n    self.view = FitFunctionOptionsView()\n  File &quot;/jenkins_workdir/workspace/pull_requests-conda-linux/qt/python/mantidqtinterfaces/mantidqtinterfaces/Muon/GUI/Common/fitting_widgets/basic_fitting/fit_function_options_view.py&quot;, line 48, in __init__\n    self.setupUi(self)\n  File &quot;&lt;string&gt;&quot;, line 71, in setupUi\nSystemError: &lt;built-in function connectSlotsByName&gt; returned a result with an error set\n\n======================================================================\nERROR: test_that_the_function_name_can_be_changed_as_expected (fit_function_options_view_test.FitFunctionOptionsViewTest)\n----------------------------------------------------------------------\nAttributeError: &#x27;FitFunctionOptionsView&#x27; object has no attribute &#x27;y&#x27;\n\nThe above exception was the direct cause of the following exception:\n\nTraceback (most recent call last):\n  File &quot;/jenkins_workdir/workspace/pull_requests-conda-linux/qt/python/mantidqtinterfaces/test/Muon/fitting_widgets/basic_fitting/fit_function_options_view_test.py&quot;, line 26, in setUp\n    self.view = FitFunctionOptionsView()\n  File &quot;/jenkins_workdir/workspace/pull_requests-conda-linux/qt/python/mantidqtinterfaces/mantidqtinterfaces/Muon/GUI/Common/fitting_widgets/basic_fitting/fit_function_options_view.py&quot;, line 48, in __init__\n    self.setupUi(self)\n  File &quot;&lt;string&gt;&quot;, line 71, in setupUi\nSystemError: &lt;built-in function connectSlotsByName&gt; returned a result with an error set\n\n======================================================================\nERROR: test_that_the_view_has_been_initialized_with_the_raw_data_option_hidden (fit_function_options_view_test.FitFunctionOptionsViewTest)\n----------------------------------------------------------------------\nAttributeError: &#x27;FitFunctionOptionsView&#x27; object has no attribute &#x27;y&#x27;\n\nThe above exception was the direct cause of the following exception:\n\nTraceback (most recent call last):\n  File &quot;/jenkins_workdir/workspace/pull_requests-conda-linux/qt/python/mantidqtinterfaces/test/Muon/fitting_widgets/basic_fitting/fit_function_options_view_test.py&quot;, line 26, in setUp\n    self.view = FitFunctionOptionsView()\n  File &quot;/jenkins_workdir/workspace/pull_requests-conda-linux/qt/python/mantidqtinterfaces/mantidqtinterfaces/Muon/GUI/Common/fitting_widgets/basic_fitting/fit_function_options_view.py&quot;, line 48, in __init__\n    self.setupUi(self)\n  File &quot;&lt;string&gt;&quot;, line 71, in setupUi\nSystemError: &lt;built-in function connectSlotsByName&gt; returned a result with an error set\n\n======================================================================\nERROR: test_that_the_view_has_been_initialized_with_the_raw_data_option_shown (fit_function_options_view_test.FitFunctionOptionsViewTest)\n----------------------------------------------------------------------\nAttributeError: &#x27;FitFunctionOptionsView&#x27; object has no attribute &#x27;y&#x27;\n\nThe above exception was the direct cause of the following exception:\n\nTraceback (most recent call last):\n  File &quot;/jenkins_workdir/workspace/pull_requests-conda-linux/qt/python/mantidqtinterfaces/test/Muon/fitting_widgets/basic_fitting/fit_function_options_view_test.py&quot;, line 26, in setUp\n    self.view = FitFunctionOptionsView()\n  File &quot;/jenkins_workdir/workspace/pull_requests-conda-linux/qt/python/mantidqtinterfaces/mantidqtinterfaces/Muon/GUI/Common/fitting_widgets/basic_fitting/fit_function_options_view.py&quot;, line 48, in __init__\n    self.setupUi(self)\n  File &quot;&lt;string&gt;&quot;, line 71, in setupUi\nSystemError: &lt;built-in function connectSlotsByName&gt; returned a result with an error set\n\n======================================================================\nERROR: test_that_update_fit_status_labels_will_display_fit_successful_if_all_fits_are_successful (fit_function_options_view_test.FitFunctionOptionsViewTest)\n----------------------------------------------------------------------\nAttributeError: &#x27;FitFunctionOptionsView&#x27; object has no attribute &#x27;y&#x27;\n\nThe above exception was the direct cause of the following exception:\n\nTraceback (most recent call last):\n  File &quot;/jenkins_workdir/workspace/pull_requests-conda-linux/qt/python/mantidqtinterfaces/test/Muon/fitting_widgets/basic_fitting/fit_function_options_view_test.py&quot;, line 26, in setUp\n    self.view = FitFunctionOptionsView()\n  File &quot;/jenkins_workdir/workspace/pull_requests-conda-linux/qt/python/mantidqtinterfaces/mantidqtinterfaces/Muon/GUI/Common/fitting_widgets/basic_fitting/fit_function_options_view.py&quot;, line 48, in __init__\n    self.setupUi(self)\n  File &quot;&lt;string&gt;&quot;, line 71, in setupUi\nSystemError: &lt;built-in function connectSlotsByName&gt; returned a result with an error set\n\n======================================================================\nERROR: test_that_update_fit_status_labels_will_display_fits_failed_if_some_of_the_fits_fail (fit_function_options_view_test.FitFunctionOptionsViewTest)\n----------------------------------------------------------------------\nAttributeError: &#x27;FitFunctionOptionsView&#x27; object has no attribute &#x27;y&#x27;\n\nThe above exception was the direct cause of the following exception:\n\nTraceback (most recent call last):\n  File &quot;/jenkins_workdir/workspace/pull_requests-conda-linux/qt/python/mantidqtinterfaces/test/Muon/fitting_widgets/basic_fitting/fit_function_options_view_test.py&quot;, line 26, in setUp\n    self.view = FitFunctionOptionsView()\n  File &quot;/jenkins_workdir/workspace/pull_requests-conda-linux/qt/python/mantidqtinterfaces/mantidqtinterfaces/Muon/GUI/Common/fitting_widgets/basic_fitting/fit_function_options_view.py&quot;, line 48, in __init__\n    self.setupUi(self)\n  File &quot;&lt;string&gt;&quot;, line 71, in setupUi\nSystemError: &lt;built-in function connectSlotsByName&gt; returned a result with an error set\n\n======================================================================\nERROR: test_that_update_fit_status_labels_will_display_no_fit_if_the_success_list_is_empty (fit_function_options_view_test.FitFunctionOptionsViewTest)\n----------------------------------------------------------------------\nAttributeError: &#x27;FitFunctionOptionsView&#x27; object has no attribute &#x27;y&#x27;\n\nThe above exception was the direct cause of the following exception:\n\nTraceback (most recent call last):\n  File &quot;/jenkins_workdir/workspace/pull_requests-conda-linux/qt/python/mantidqtinterfaces/test/Muon/fitting_widgets/basic_fitting/fit_function_options_view_test.py&quot;, line 26, in setUp\n    self.view = FitFunctionOptionsView()\n  File &quot;/jenkins_workdir/workspace/pull_requests-conda-linux/qt/python/mantidqtinterfaces/mantidqtinterfaces/Muon/GUI/Common/fitting_widgets/basic_fitting/fit_function_options_view.py&quot;, line 48, in __init__\n    self.setupUi(self)\n  File &quot;&lt;string&gt;&quot;, line 71, in setupUi\nSystemError: &lt;built-in function connectSlotsByName&gt; returned a result with an error set\n\n======================================================================\nERROR: test_that_update_function_browser_parameters_will_clear_the_function_if_the_function_provided_is_none (fit_function_options_view_test.FitFunctionOptionsViewTest)\n----------------------------------------------------------------------\nAttributeError: &#x27;FitFunctionOptionsView&#x27; object has no attribute &#x27;y&#x27;\n\nThe above exception was the direct cause of the following exception:\n\nTraceback (most recent call last):\n  File &quot;/jenkins_workdir/workspace/pull_requests-conda-linux/qt/python/mantidqtinterfaces/test/Muon/fitting_widgets/basic_fitting/fit_function_options_view_test.py&quot;, line 26, in setUp\n    self.view = FitFunctionOptionsView()\n  File &quot;/jenkins_workdir/workspace/pull_requests-conda-linux/qt/python/mantidqtinterfaces/mantidqtinterfaces/Muon/GUI/Common/fitting_widgets/basic_fitting/fit_function_options_view.py&quot;, line 48, in __init__\n    self.setupUi(self)\n  File &quot;&lt;string&gt;&quot;, line 71, in setupUi\nSystemError: &lt;built-in function connectSlotsByName&gt; returned a result with an error set\n\n======================================================================\nERROR: test_that_update_function_browser_parameters_will_set_the_function_if_in_simultaneous_mode (fit_function_options_view_test.FitFunctionOptionsViewTest)\n----------------------------------------------------------------------\nAttributeError: &#x27;FitFunctionOptionsView&#x27; object has no attribute &#x27;y&#x27;\n\nThe above exception was the direct cause of the following exception:\n\nTraceback (most recent call last):\n  File &quot;/jenkins_workdir/workspace/pull_requests-conda-linux/qt/python/mantidqtinterfaces/test/Muon/fitting_widgets/basic_fitting/fit_function_options_view_test.py&quot;, line 26, in setUp\n    self.view = FitFunctionOptionsView()\n  File &quot;/jenkins_workdir/workspace/pull_requests-conda-linux/qt/python/mantidqtinterfaces/mantidqtinterfaces/Muon/GUI/Common/fitting_widgets/basic_fitting/fit_function_options_view.py&quot;, line 48, in __init__\n    self.setupUi(self)\n  File &quot;&lt;string&gt;&quot;, line 71, in setupUi\nSystemError: &lt;built-in function connectSlotsByName&gt; returned a result with an error set\n\n======================================================================\nERROR: test_that_update_function_browser_parameters_will_update_the_parameters_of_the_function_for_single_fit (fit_function_options_view_test.FitFunctionOptionsViewTest)\n----------------------------------------------------------------------\nAttributeError: &#x27;FitFunctionOptionsView&#x27; object has no attribute &#x27;y&#x27;\n\nThe above exception was the direct cause of the following exception:\n\nTraceback (most recent call last):\n  File &quot;/jenkins_workdir/workspace/pull_requests-conda-linux/qt/python/mantidqtinterfaces/test/Muon/fitting_widgets/basic_fitting/fit_function_options_view_test.py&quot;, line 26, in setUp\n    self.view = FitFunctionOptionsView()\n  File &quot;/jenkins_workdir/workspace/pull_requests-conda-linux/qt/python/mantidqtinterfaces/mantidqtinterfaces/Muon/GUI/Common/fitting_widgets/basic_fitting/fit_function_options_view.py&quot;, line 48, in __init__\n    self.setupUi(self)\n  File &quot;&lt;string&gt;&quot;, line 71, in setupUi\nSystemError: &lt;built-in function connectSlotsByName&gt; returned a result with an error set\n\n----------------------------------------------------------------------\nRan 19 tests in 0.107s\n\nFAILED (errors=19)\n\n          Start 2185: python.MuonQt5.fit_function_options_view_test.fit_function_options_view_test\n"
            }
        },
        {
            "test_name": "mantidqt_qt5.test_interpreter.test_interpreter",
            "latest_failed_build": "2275",
            "agent_name": "Linux",
            "last_failed_outcome": "Flake",
            "pipeline_name": "pull_requests-conda-linux",
            "problem_count": 1,
            "past_outcome": {
                "build_keys": [
                    "2279",
                    "2278",
                    "2277",
                    "2276",
                    "2275",
                    "2274",
                    "2273",
                    "2272",
                    "2271",
                    "2270",
                    "2269",
                    "2268",
                    "2267",
                    "2266",
                    "2265",
                    "2264",
                    "2263",
                    "2262",
                    "2261",
                    "2260",
                    "2259",
                    "2258",
                    "2257",
                    "2256",
                    "2255",
                    "2254",
                    "2253",
                    "2252",
                    "2251",
                    "2250"
                ],
                "past_outcome_list": [
                    "None",
                    "Passed",
                    "Passed",
                    "Passed",
                    "Flake",
                    "Passed",
                    "Passed",
                    "Passed",
                    "Passed",
                    "Passed",
                    "Passed",
                    "Passed",
                    "Passed",
                    "Passed",
                    "Passed",
                    "Passed",
                    "Passed",
                    "Passed",
                    "Passed",
                    "Passed",
                    "Passed",
                    "Passed",
                    "None",
                    "Passed",
                    "Passed",
                    "Passed",
                    "None",
                    "None",
                    "None",
                    "None"
                ]
            },
            "last_stack_traces": {
                "test_name": "mantidqt_qt5.test_interpreter.test_interpreter",
                "build": "2275",
                "agent_name": "Linux",
                "trial": 1,
                "outcome": "Timeout",
                "test_time": "1200.09",
                "stacktrace": "QStandardPaths: XDG_RUNTIME_DIR not set, defaulting to &#x27;/tmp/runtime-abc&#x27;\nlibEGL warning: DRI2: failed to open swrast (search paths /usr/lib64/dri)\nlibEGL warning: DRI2: failed to open swrast (search paths /usr/lib64/dri)\nlibEGL warning: DRI2: failed to open swrast (search paths /usr/lib64/dri)\nlibEGL warning: DRI2: failed to open swrast (search paths /usr/lib64/dri)\nQXcbIntegration: Cannot create platform OpenGL context, neither GLX nor EGL are enabled\n.........\n----------------------------------------------------------------------\nRan 9 tests in 0.144s\n\nOK\nthis is a string\nthis is a string\n\n          Start 2038: mantidqt_qt5.test_interpreter.test_interpreter\n"
            }
        }
    ]
}